Workbook

Sheet Cover
A1: BASF SE company model and consensus bridge
A2: Primary-file actuals through 2026Q2; Morgan Stanley and Citi estimates as external consensus anchors
A4: Model identity
A5: Company | B5: BASF SE
A6: Ticker | B6: BAS.DE / BASFn.DE
A7: Currency / unit | B7: EUR million unless stated
A8: Annual history | B8: 2025A
A9: Quarterly history | B9: 2026Q2 / H1 2026
A10: Annual forecast | B10: 2026E–2028E
A11: Quarterly forecast | B11: 2026-08-14
A12: Model date | B12: 2026-09-03
A13: Version | B13: BASF v0.4 — Citi EU-policy scenario audit; v0.3 retained
A15: Critical boundary notes
A16: Historical and reported figures are BASF primary-file values. Morgan Stanley figures are clearly labelled external estimates, not Dalton estimates.
A17: 2026 adjusted EPS bridge is consensus-methodology EPS; it is not identical to reported IFRS EPS or net income.
A18: Nutrition & Care pricing and D&A are not disclosed by Morgan Stanley as separate euro deltas. Residual EPS revisions are therefore kept unallocated.
A19: Citi uses two group measures: segment-bridge EBITDA before special items (€7,567m/€7,656m for 2026/27) and standardized adjusted EBITDA (€7,608m/€7,721m/€8,561m for 2026/27/28). They are not mixed.
A20: Citi 2028 divisional EBITDA before special items is not disclosed in the report; only group standardized P&L estimates are recorded.
A21: Q2 2026 D&A includes €1,028m group D&A and €144m Nutrition & Care D&A. No annualization is treated as company guidance.
A22: NPG/HDO list-price increases are excluded from forecasts until realized European transaction pricing, volume and contribution margin are verified.
A24: Color convention
A25: Primary-file actual | B25: Aa123
A26: Formula | B26: Aa123
A27: Cross-sheet formula | B27: Aa123
A28: External estimate | B28: Aa123
A29: Analyst assumption / unresolved bridge | B29: Aa123

Sheet Segment Model
A1: BASF segment model — primary-file actuals
A2: EUR million unless stated | B2: 2025A | C2: 2026Q2A | D2: 2026H1A | E2: 2026E | F2: 2027E | G2: 2028E
A4: Chemicals
A5: Sales | B5: 10055 | C5: 3595 | D5: 6257
A6: EBITDA before special items | B6: 853 | C6: 377 | D6: 610
A7: EBITDA margin before special items | B7: =IFERROR(B6/B5,"") -> 0.084833416 | C7: =IFERROR(C6/C5,"") -> 0.10486787 | D7: =IFERROR(D6/D5,"") -> 0.09749081
A8: Depreciation & amortization | B8: 1120 | C8: 310 | D8: 595
A9: EBIT before special items | B9: =IF(OR(B6="",B8=""),"",B6-B8) -> -267 | C9: =IF(OR(C6="",C8=""),"",C6-C8) -> 67 | D9: =IF(OR(D6="",D8=""),"",D6-D8) -> 15
A11: Materials
A12: Sales | B12: 12742 | C12: 3790 | D12: 7028
A13: EBITDA before special items | B13: 1575 | C13: 792 | D13: 1303
A14: EBITDA margin before special items | B14: =IFERROR(B13/B12,"") -> 0.12360697 | C14: =IFERROR(C13/C12,"") -> 0.20897098 | D14: =IFERROR(D13/D12,"") -> 0.18540125
A15: Depreciation & amortization | B15: 867 | C15: 189 | D15: 375
A16: EBIT before special items | B16: =IF(OR(B13="",B15=""),"",B13-B15) -> 708 | C16: =IF(OR(C13="",C15=""),"",C13-C15) -> 603 | D16: =IF(OR(D13="",D15=""),"",D13-D15) -> 928
A18: Industrial Solutions
A19: Sales | B19: 8594 | C19: 2328 | D19: 4420
A20: EBITDA before special items | B20: 1200 | C20: 434 | D20: 795
A21: EBITDA margin before special items | B21: =IFERROR(B20/B19,"") -> 0.1396323 | C21: =IFERROR(C20/C19,"") -> 0.18642612 | D21: =IFERROR(D20/D19,"") -> 0.17986425
A22: Depreciation & amortization | B22: 448 | C22: 148 | D22: 243
A23: EBIT before special items | B23: =IF(OR(B20="",B22=""),"",B20-B22) -> 752 | C23: =IF(OR(C20="",C22=""),"",C20-C22) -> 286 | D23: =IF(OR(D20="",D22=""),"",D20-D22) -> 552
A25: Nutrition & Care
A26: Sales | B26: 6509 | C26: 1709 | D26: 3378
A27: EBITDA before special items | B27: 649 | C27: 204 | D27: 396
A28: EBITDA margin before special items | B28: =IFERROR(B27/B26,"") -> 0.099708096 | C28: =IFERROR(C27/C26,"") -> 0.11936805 | D28: =IFERROR(D27/D26,"") -> 0.11722913
A29: Depreciation & amortization | B29: 554 | C29: 144 | D29: 282
A30: EBIT before special items | B30: =IF(OR(B27="",B29=""),"",B27-B29) -> 95 | C30: =IF(OR(C27="",C29=""),"",C27-C29) -> 60 | D30: =IF(OR(D27="",D29=""),"",D27-D29) -> 114
A32: Surface Technologies
A33: Sales | B33: 8967 | C33: 2625 | D33: 5031
A34: EBITDA before special items | B34: 800 | C34: 115 | D34: 391
A35: EBITDA margin before special items | B35: =IFERROR(B34/B33,"") -> 0.089216014 | C35: =IFERROR(C34/C33,"") -> 0.043809524 | D35: =IFERROR(D34/D33,"") -> 0.077718147
A36: Depreciation & amortization | B36: 253 | C36: 50 | D36: 102
A37: EBIT before special items | B37: =IF(OR(B34="",B36=""),"",B34-B36) -> 547 | C37: =IF(OR(C34="",C36=""),"",C34-C36) -> 65 | D37: =IF(OR(D34="",D36=""),"",D34-D36) -> 289
A39: Agricultural Solutions
A40: Sales | B40: 9587 | C40: 2210 | D40: 5315
A41: EBITDA before special items | B41: 2081 | C41: 448 | D41: 1550
A42: EBITDA margin before special items | B42: =IFERROR(B41/B40,"") -> 0.21706478 | C42: =IFERROR(C41/C40,"") -> 0.20271493 | D42: =IFERROR(D41/D40,"") -> 0.29162747
A43: Depreciation & amortization | B43: 583 | C43: 140 | D43: 274
A44: EBIT before special items | B44: =IF(OR(B41="",B43=""),"",B41-B43) -> 1498 | C44: =IF(OR(C41="",C43=""),"",C41-C43) -> 308 | D44: =IF(OR(D41="",D43=""),"",D41-D43) -> 1276
A46: Other / reconciliation
A47: Sales | B47: 3202 | C47: 948 | D47: 1797
...

Sheet Consensus Bridge
A1: Morgan Stanley post-2Q26 estimate bridge
A2: Metric | B2: 2025A | C2: 2026E | D2: 2027E | E2: 2028E | F2: Method / boundary
A3: MS sales | C3: 61053 | D3: 63400.15 | E3: 65111.95 | F3: 2027–28 inferred from MS sales growth 0.5% / 2.7%; 2026 direct
A4: MS sales growth | C4: 0.02 | D4: 0.005 | E4: 0.027 | F4: MS report p.3
A5: MS EBITDA | C5: 7728 | D5: 7798.2185 | E5: 8139.9937 | F5: 2027–28 = sales × MS EBITDA margin; 2026 direct
A6: MS EBITDA margin | C6: 0.127 | D6: 0.123 | E6: 0.125 | F6: MS report p.3; 2026 direct EBITDA/sales gives 12.66%, rounds to 12.7%
A7: MS adjusted EPS — old | C7: 3.46 | D7: 3.14 | E7: 3.49 | F7: MS pre-update estimate shown in 2026-08-12 report
A8: MS adjusted EPS — new | B8: 2.24 | C8: 3.44 | D8: 3.12 | E8: 3.39 | F8: MS 2026-08-12 post-Q2 update
A9: Absolute EPS revision | C9: -0.02 | D9: -0.02 | E9: -0.1 | F9: New minus old
A10: EPS revision % | C10: -0.006 | D10: -0.008 | E10: -0.028 | F10: MS reported rounded revision
A11: Reason 1 | C11: Slightly lower Nutrition & Care pricing | D11: Slightly lower Nutrition & Care pricing | E11: Slightly lower Nutrition & Care pricing | F11: No euro allocation disclosed
A12: Reason 2 | C12: Slightly higher D&A at Q2 run rate | D12: Slightly higher D&A at Q2 run rate | E12: Slightly higher D&A at Q2 run rate | F12: No euro allocation disclosed
A13: Unallocated residual | C13: -0.02 | D13: -0.02 | E13: -0.1 | F13: Entire revision remains unallocated; do not invent split
A14: MS price target | C14: 56 | D14: 56 | E14: 56 | F14: Unchanged; rating Overweight
A15: Share price, Aug 11 | C15: 51.26 | F15: MS cover page
A16: Upside to price target | C16: =C14/C15-1 -> 0.092469762 | F16: Formula
A19: MS vs mean consensus (2026E) | B19: MS | C19: Mean consensus | D19: MS premium / (discount) | F19: The report extraction also displays a second value set; only the clearly ordered MS-vs-Mean columns are used here.
A20: Sales | B20: 61053 | C20: 60406 | D20: =B20/C20-1 -> 0.010710857
A21: EBITDA | B21: 7728 | C21: 6945 | D21: =B21/C21-1 -> 0.11274298
A22: EBIT | B22: 3921 | C22: 2699 | D22: =B22/C22-1 -> 0.45276028
A23: Adjusted EPS | B23: 3.44 | C23: 1.71 | D23: =B23/C23-1 -> 1.0116959

Sheet Citi Bridge
A1: Citi post-Q2 2026 consensus and volume-recovery bridge
A2: Metric | B2: 2025A | C2: 2026E | D2: 2027E | E2: 2028E | F2: 2026 consensus | G2: 2027 consensus | H2: Method / boundary
A3: Citi sales — standardized P&L | B3: 59657 | C3: 64482.5 | D3: 66503.6 | E3: 69944.9 | H3: Citi standardized financial summary; not the same perimeter as Figure 3 segment table.
A4: Citi adjusted EBITDA — standardized P&L | B4: 6554 | C4: 7608 | D4: 7721 | E4: 8561 | H4: Citi standardized financial summary.
A5: Citi adjusted EBITDA margin | C5: =C4/C3 -> 0.1179855 | D5: =D4/D3 -> 0.11609898 | E5: =E4/E3 -> 0.12239634 | H5: Formula.
A6: Citi group sales — Figure 3 segment bridge | B6: 59657 | C6: 63830 | D6: 65757 | F6: 62837 | G6: 63717 | H6: Figure 3; comparable to the divisional forecast table.
A7: Citi EBITDA bsi — Figure 3 segment bridge | B7: 6554 | C7: 7567 | D7: 7656 | F7: 7759 | G7: 7725 | H7: Figure 3; this is the measure compared with BASF guidance.
A8: Citi EBITDA bsi margin | C8: =C7/C6 -> 0.11854927 | D8: =D7/D6 -> 0.11642867 | F8: =F7/F6 -> 0.12347821 | G8: =G7/G6 -> 0.12123923 | H8: Formula.
A9: BASF official EBITDA bsi guidance — low | C9: 6900 | H9: BASF H1 2026 report, pp.3/15.
A10: BASF official EBITDA bsi guidance — high | C10: 7700 | H10: BASF H1 2026 report, pp.3/15.
A11: BASF official guidance midpoint | C11: =AVERAGE(C9:C10) -> 7300 | H11: Formula; guidance midpoint is not management point estimate.
A12: Citi bsi vs official midpoint | C12: =C7/C11-1 -> 0.036575342 | H12: Formula.
A13: Citi bsi vs official high | C13: =C7/C10-1 -> -0.017272727 | H13: Formula.
A14: Morgan Stanley EBITDA | C14: ='Consensus Bridge'!C5 -> 7728 | D14: ='Consensus Bridge'!D5 -> 7798.2185 | E14: ='Consensus Bridge'!E5 -> 8139.9937 | H14: Linked from MS bridge; 2027–28 are inferred there from MS sales × margin.
A15: Citi bsi vs MS EBITDA | C15: =C7/C14-1 -> -0.020833333 | D15: =D7/D14-1 -> -0.0182373 | H15: 2026–27 only; close but not guaranteed identical broker definitions.
A16: Citi standardized adj. EBITDA vs MS | C16: =C4/C14-1 -> -0.01552795 | D16: =D4/D14-1 -> -0.009902063 | E16: =E4/E14-1 -> 0.051720709 | H16: Broader group comparison; preserve definition warning.
A17: Citi Figure 3 sales vs MS sales | C17: =C6/'Consensus Bridge'!C3-1 -> 0.04548507 | D17: =D6/'Consensus Bridge'!D3-1 -> 0.037174202 | H17: Different broker perimeter/FX assumptions may contribute.
A18: Citi target price (€) | C18: 58 | D18: 58 | E18: 58 | H18: Unchanged; Buy.
A19: Citi reference share price (€) | C19: 50.17 | H19: Close 2026-08-13.
A20: Upside to Citi target | C20: =C18/C19-1 -> 0.15606936 | H20: Formula; excludes dividend.
A21: Citi 2027 EV/EBITDA | D21: 7.7 | H21: Above Citi-stated five-year historical average of 7.3x.
A22: Citi mid-cycle EBITDA | D22: 9150 | H22: Midpoint of Citi €9.1–9.2bn range; report says 2027 is ~16% below normalized.
A23: 2027 discount to Citi mid-cycle | D23: =D4/D22-1 -> -0.15617486 | H23: Uses standardized adjusted EBITDA for internal consistency.
A26: Citi divisional EBITDA before special items
A27: Segment | B27: 2026E Citi | C27: 2026E consensus | D27: Citi premium / (discount) | E27: 2027E Citi | F27: 2027E consensus | G27: Citi premium / (discount) | H27: 2027E vs 2026E
A28: Chemicals | B28: 1123 | C28: 1380 | D28: =B28/C28-1 -> -0.18623188 | E28: 1549 | F28: 1529 | G28: =E28/F28-1 -> 0.013080445 | H28: =E28/B28-1 -> 0.37934105
A29: Materials | B29: 2181 | C29: 2120 | D29: =B29/C29-1 -> 0.028773585 | E29: 1914 | F29: 1857 | G29: =E29/F29-1 -> 0.030694669 | H29: =E29/B29-1 -> -0.12242091
A30: Industrial Solutions | B30: 1400 | C30: 1384 | D30: =B30/C30-1 -> 0.011560694 | E30: 1385 | F30: 1407 | G30: =E30/F30-1 -> -0.015636105 | H30: =E30/B30-1 -> -0.010714286
A31: Surface Technologies | B31: 653 | C31: 674 | D31: =B31/C31-1 -> -0.03115727 | E31: 587 | F31: 673 | G31: =E31/F31-1 -> -0.12778603 | H31: =E31/B31-1 -> -0.10107198
A32: Nutrition & Care | B32: 662 | C32: 735 | D32: =B32/C32-1 -> -0.099319728 | E32: 712 | F32: 795 | G32: =E32/F32-1 -> -0.10440252 | H32: =E32/B32-1 -> 0.075528701
A33: Agricultural Solutions | B33: 2007 | C33: 2033 | D33: =B33/C33-1 -> -0.012788982 | E33: 2059 | F33: 2084 | G33: =E33/F33-1 -> -0.011996161 | H33: =E33/B33-1 -> 0.025909317
A34: Other / reconciliation | B34: -459 | C34: -536 | D34: =B34/C34-1 -> -0.14365672 | E34: -550 | F34: -586 | G34: =E34/F34-1 -> -0.061433447 | H34: =E34/B34-1 -> 0.19825708
A35: Group / segment sum | B35: =SUM(B28:B34) -> 7567 | C35: =SUM(C28:C34) -> 7790 | D35: =B35/C35-1 -> -0.028626444 | E35: =SUM(E28:E34) -> 7656 | F35: =SUM(F28:F34) -> 7759 | G35: =E35/F35-1 -> -0.013274907 | H35: =E35/B35-1 -> 0.011761596
A38: Citi 2026 EBITDA bsi bridge from 2025A
A39: Bridge component | B39: €m | C39: % of 2025A EBITDA | H39: Boundary
A40: 2025A EBITDA bsi | B40: 6554 | C40: =B40/$B$40 -> 1 | H40: BASF actual
A41: China Verbund | B41: 200 | C41: =B41/$B$40 -> 0.030515716 | H41: Citi estimate
A42: Underlying volumes | B42: 571 | C42: =B42/$B$40 -> 0.087122368 | H42: Citi estimate
A43: Net pricing upstream | B43: 477 | C43: =B43/$B$40 -> 0.072779982 | H43: Citi estimate
A44: Temporary Middle East gains | B44: 169 | C44: =B44/$B$40 -> 0.02578578 | H44: Citi estimate
...

Sheet EU Policy Scenario
A1: Citi EU chemical-protection scenario — audit bridge (not booked in base case)
A2: EUR million unless stated. Blue cells are Citi assumptions/estimates; black cells are formulas; green cells link to prior sheets.
A4: Forecast revisions versus Citi 2026-08-14
A5: Metric | B5: 2026E new | C5: 2026E prior | D5: Delta | E5: 2027E new | F5: 2027E prior | G5: Delta | H5: 2028E new | I5: 2028E prior | J5: Delta | K5: Boundary
A6: Sales | B6: 64108.3 | C6: ='Citi Bridge'!C3 -> 64482.5 | D6: =B6-C6 -> -374.2 | E6: 66026.4 | F6: ='Citi Bridge'!D3 -> 66503.6 | G6: =E6-F6 -> -477.2 | H6: 69450.1 | I6: ='Citi Bridge'!E3 -> 69944.9 | J6: =H6-I6 -> -494.8 | K6: Citi standardized P&L; new report Figure 3 uses same displayed values.
A7: Adjusted EBITDA / EBITDA bsi | B7: 7578 | C7: ='Citi Bridge'!C4 -> 7608 | D7: =B7-C7 -> -30 | E7: 7652 | F7: ='Citi Bridge'!D4 -> 7721 | G7: =E7-F7 -> -69 | H7: 8488 | I7: ='Citi Bridge'!E4 -> 8561 | J7: =H7-I7 -> -73 | K7: Citi page 2 labels EBITDA Adj.; Figure 3 labels EBITDA bsi. Retained as broker measure, not Dalton base case.
A8: Adjusted diluted EPS (€) | B8: 2.78 | C8: 2.8 | D8: =B8-C8 -> -0.02 | E8: 2.58 | F8: 2.63 | G8: =E8-F8 -> -0.05 | H8: 3.5 | I8: 3.56 | J8: =H8-I8 -> -0.06 | K8: Citi new versus old, 2026-09-03.
A9: Free cash flow | B9: 1470 | C9: 1230 | D9: =B9-C9 -> 240 | E9: 3427 | F9: 3551 | G9: =E9-F9 -> -124 | K9: Citi Figure 3; 2028 old/new comparison not disclosed.
A12: Citi pricing scenario
A13: Assumption / output | B13: Low | C13: High | D13: Unit | E13: Formula / boundary
A14: European upstream capacity | B14: 10 | C14: 10 | D14: million tonnes | E14: Citi assumption; BASF does not disclose a matching audited product map.
A15: Utilization applied | B15: 0.75 | C15: 0.75 | D15: % | E15: Citi assumption.
A16: External sales share | B16: 0.75 | C16: 0.8 | D16: % | E16: Citi states 75–80% of Chemicals sales are external.
A17: Net spread improvement | B17: 100 | C17: 100 | D17: €/tonne | E17: Illustrative broad safeguarding scenario; not enacted policy.
A18: Recalculated pricing EBITDA uplift | B18: =B14*1000000*B15*B16*B17/1000000 -> 562.5 | C18: =C14*1000000*C15*C16*C17/1000000 -> 600 | D18: €m | E18: 10mt × utilization × external share × €100/t = €562.5–600.0m.
A19: Citi stated pricing uplift | B19: 500 | C19: 600 | D19: €m | E19: Rounded range in report.
A22: Citi market-share / utilization scenario and arithmetic audit
A23: Assumption / output | B23: Low | C23: High | D23: Unit | E23: Formula / boundary
A24: European upstream market share base | B24: 0.25 | C24: 0.25 | D24: % | E24: Citi uses ~25% base for its 8–12% volume-growth calculation.
A25: Market-share recovery | B25: 0.02 | C25: 0.03 | D25: ppt | E25: Citi assumption.
A26: Europe share of group sales | B26: 0.4 | C26: 0.4 | D26: % | E26: Citi assumption; not a same-perimeter capacity weight.
A27: European utilization base | B27: 0.74 | C27: 0.74 | D27: % | E27: Citi assumption.
A28: Citi stated end utilization | B28: 0.78 | C28: 0.81 | D28: % | E28: Citi stated ~78–81%.
A29: Citi stated utilization increase | B29: 4 | C29: 6 | D29: ppt | E29: Citi stated ~4–6ppt.
A30: Citi modeled sensitivity | B30: 200 | C30: 200 | D30: €m / ppt | E30: Citi says closer to €200m per ppt than management indication of ~€300m.
A31: Implied European volume growth | B31: =B25/B24 -> 0.08 | C31: =C25/C24 -> 0.12 | D31: % | E31: 2–3ppt share gain / 25% base = 8–12%.
A32: Implied group volume uplift | B32: =B31*B26 -> 0.032 | C32: =C31*C26 -> 0.048 | D32: % | E32: 8–12% Europe volume growth × 40% sales exposure = 3.2–4.8%.
A33: Mechanical end utilization | B33: =B27*(1+B31) -> 0.7992 | C33: =C27*(1+C31) -> 0.8288 | D33: % | E33: 74% × (1 + 8–12%) = 79.9–82.9%, above Citi stated 78–81%.
A34: Mechanical utilization increase | B34: =(B33-B27)*100 -> 5.92 | C34: =(C33-C27)*100 -> 8.88 | D34: ppt | E34: 5.9–8.9ppt, not Citi stated 4–6ppt.
A35: Unscaled uplift at €200m / ppt | B35: =B29*B30 -> 800 | C35: =C29*C30 -> 1200 | D35: €m | E35: €800–1,200m; does not reconcile to Citi stated €400–600m.
A36: 40%-prorated uplift at €200m / ppt | B36: =B29*B30*B26 -> 320 | C36: =C29*C30*C26 -> 480 | D36: €m | E36: €320–480m; still below Citi stated range. Sales exposure is not necessarily capacity/EBITDA weight.
A37: Citi stated utilization EBITDA uplift | B37: 400 | C37: 600 | D37: €m | E37: This implies €100m per European utilization ppt, not the text’s €200m.
A38: Effective sensitivity implied by stated uplift | B38: =B37/B29 -> 100 | C38: =C37/C29 -> 100 | D38: €m / ppt | E38: €100m / ppt at both bounds.
A41: Scenario bridge to Citi 2027E and valuation boundary
A42: Metric | B42: Value | C42: Unit | D42: Formula / boundary
A43: Citi new 2027E adjusted EBITDA | B43: =E7 -> 7652 | C43: €m | D43: Linked within this sheet.
A44: Illustrative gross EU protection uplift | B44: 1000 | C44: €m | D44: Citi says up to ~€1bn; gross, pre-retaliation and implementation.
A45: Scenario 2027E EBITDA | B45: =B43+B44 -> 8652 | C45: €m | D45: Not a forecast and not booked in base case.
A46: Scenario uplift vs 2027E | B46: =B44/B43 -> 0.13068479 | C46: % | D46: €1bn / €7.652bn.
A47: Citi mid-cycle EBITDA | B47: 9150 | C47: €m | D47: Midpoint / chart reference ~€9.15bn.
...

Sheet Driver Audit
A1: Post-2Q26 driver audit
A2: Metric | B2: 2025A | C2: 2026Q2A | D2: 2026H1A | E2: Interpretation / model treatment
A3: Group D&A | B3: 3984 | C3: 1028 | D3: 1953 | E3: Q2 +10.9% YoY; H1 +6.3% YoY. Q2×4 = 4,112, a run-rate observation, not guidance.
A4: Nutrition & Care D&A | B4: 554 | C4: 144 | D4: 282 | E4: Q2 +4.7% YoY; H1 +7.6% YoY. Helps explain EPS sensitivity despite EBITDA improvement.
A5: Nutrition & Care sales | B5: 6509 | C5: 1709 | D5: 3378 | E5: Q2 +5.7% YoY; H1 +1.2% YoY.
A6: Nutrition & Care EBITDA bsi | B6: 649 | C6: 204 | D6: 396 | E6: Q2 +4.2% YoY; H1 -6.9% YoY.
A7: Nutrition & Care EBITDA margin | B7: 0.1 | C7: 0.119 | D7: 0.117 | E7: Q2 11.9% vs 12.1% prior year; H1 11.7% vs 12.7% prior year.
A8: Nutrition & Care price effect | C8: -0.017 | E8: Q2 segment price effect -1.7%; Nutrition & Health -8.0%, Care Chemicals +0.5%.
A9: NPG/HDO announced European list price | E9: Excluded. No realized transaction price, Europe volume or segment attribution to Nutrition & Care.
A12: Mechanical diagnostics
A13: Q2 group D&A annualized | B13: =C3*4 -> 4112 | C13: Observation only
A14: Q2 N&C D&A annualized | B14: =C4*4 -> 576 | C14: Observation only
A15: 2026 EPS delta (€ / share) | B15: ='Consensus Bridge'!C9 -> -0.02 | C15: Not allocated between pricing and D&A

Sheet Sources
A1: Sheet | B1: Field | C1: Period | D1: Source / document | E1: Document date | F1: Reference | G1: URL | H1: Boundary / methodology | I1: Verified?
A2: Segment Model | B2: 2025 segment and group actuals | C2: 2025A | D2: BASF Report 2025 | E2: 2026-02-27 | F2: Group p.52; segments pp.66–80 | G2: https://www.basf.com/dam/jcr:d54ddca4-f9c7-4b4f-b65e-d6ae3188ee24/basf/www/global/documents/en/investor-relations/calendar-and-publications/reports/2026/BASF_Report_2025.pdf | H2: Primary-file values; discontinued Coatings presentation follows BASF report | I2: Yes
A3: Segment Model | B3: 2026Q2/H1 segment and group actuals | C3: 2026Q2/H1 | D3: BASF Half-Year Financial Report 2026 | E3: 2026-07-29 | F3: Group pp.3–8; segments pp.19–31 | G3: https://www.basf.com/dam/jcr:0b80a486-0dd8-4706-9d1c-3c7658e9c5c0/basf/www/global/documents/en/investor-relations/calendar-and-publications/reports/2026/BASF_Half-Year-Financial-Report-2026.pdf | H3: Primary-file values | I3: Yes
A4: Consensus Bridge | B4: MS EPS, sales, EBITDA, margins, PT | C4: 2026E–2028E | D4: Morgan Stanley, BASF Risk Reward Update | E4: 2026-08-12 | F4: pp.1–3 | G4: alphaengine://document/320000610115010 | H4: External analyst estimates; 2027–28 sales/EBITDA derived only where noted | I4: Yes
A5: Driver Audit | B5: NPG/HDO list price action | C5: 2026-08-12 | D5: BASF official release P-26-150 | E5: 2026-08-12 | F5: Official release | G5: https://www.basf.com/global/en/media/news-releases/2026/08/p-26-150 | H5: Excluded from forecast absent realization evidence | I5: Yes
A6: Citi Bridge | B6: Citi segment sales/EBITDA, group P&L, volume sensitivity and target price | C6: 2026E–2028E | D6: Citi, BASF SE: Less risky than Air Liquide? | E6: 2026-08-14 | F6: pp.1–4 / Figures 1–3 | G6: alphaengine://document/320000610125576 | H6: External analyst estimates; Figure 3 EBITDA bsi kept separate from standardized adjusted EBITDA | I6: Yes
A7: EU Policy Scenario | B7: Citi forecast revision, pricing/utilization scenario, TP | C7: 2026E–2028E | D7: Citi, BASF SE: Protecting Europe: The Next Leg Higher? | E7: 2026-09-03 | F7: pp.1–7 / Figures 2–3 | G7: alphaengine://document/320000610261263 | H7: External estimates and illustrative gross policy scenario; arithmetic independently audited | I7: Yes
A8: EU Policy Scenario | B8: CCA framework, official deliverables and import monitor | C8: 2025–2026 | D8: European Commission, Chemical Industry Action Plan / Critical Chemicals Alliance | E8: 2026-09-03 | F8: Official webpages | G8: https://single-market-economy.ec.europa.eu/sectors/chemicals/critical-chemicals-alliance_en | H8: Official framework; no broad enacted €100/t safeguard found | I8: Yes
A9: EU Policy Scenario | B9: BDO, adipic acid and polyamide-yarn anti-dumping measures | C9: 2026 | D9: European Commission trade-defence releases | E9: 2026-05-05 to 2026-07-28 | F9: Official releases | G9: https://policy.trade.ec.europa.eu/news/commission-imposes-anti-dumping-duties-imports-bdo-three-countries-2026-06-24_en | H9: Product-specific measures; not a sector-wide safeguard | I9: Yes
A10: EU Policy Scenario | B10: China response to proposed overcapacity instrument | C10: 2026 | D10: MOFCOM regular press conference | E10: 2026-05-21 | F10: Official statement | G10: https://english.mofcom.gov.cn/News/PressConference/art/2026/art_fe232668f62042d28245dd87ea2bfaba.html | H10: Explicit retaliation warning; no quantified BASF impact | I10: Yes
A11: EU Policy Scenario | B11: Practitioner view on product-specific measures and mass commodities | C11: 2026 | D11: Guidepoint, former BASF Managing Director | E11: 2026-05-12 | F11: Relevant Q&A pairs | G11: https://platform.guidepoint.com/transcript?id=D34B1F3D-D1AF-4B5E-8B73-1857E370841F | H11: Practitioner opinion; not primary policy evidence | I11: Yes

Sheet Checks
A1: Check | B1: Value / difference | C1: Tolerance | D1: Status | E1: Notes | F1: Last run
A2: Group 2025 sales equals segment sum | B2: =SUM('Segment Model'!B5,'Segment Model'!B12,'Segment Model'!B19,'Segment Model'!B26,'Segment Model'!B33,'Segment Model'!B40,'Segment Model'!B47)-'Segment Model'!B54 -> -1 | C2: 1 | D2: =IF(ABS(B2)<=C2,"OK","ERROR") -> OK | E2: €1m rounding tolerance | F2: 2026-08-12
A3: Group Q2 sales equals segment sum | B3: =SUM('Segment Model'!C5,'Segment Model'!C12,'Segment Model'!C19,'Segment Model'!C26,'Segment Model'!C33,'Segment Model'!C40,'Segment Model'!C47)-'Segment Model'!C54 -> -1 | C3: 1 | D3: =IF(ABS(B3)<=C3,"OK","ERROR") -> OK | E3: €1m rounding tolerance | F3: 2026-08-12
A4: Group H1 sales equals segment sum | B4: =SUM('Segment Model'!D5,'Segment Model'!D12,'Segment Model'!D19,'Segment Model'!D26,'Segment Model'!D33,'Segment Model'!D40,'Segment Model'!D47)-'Segment Model'!D54 -> 0 | C4: 1 | D4: =IF(ABS(B4)<=C4,"OK","ERROR") -> OK | E4: €1m rounding tolerance | F4: 2026-08-12
A5: MS 2026 EPS absolute revision | B5: ='Consensus Bridge'!C8-'Consensus Bridge'!C7 -> -0.02 | C5: 0 | D5: =IF(ABS(B5-'Consensus Bridge'!C9)<=0.000001,"OK","ERROR") -> OK | E5: New minus old | F5: 2026-08-12
A6: MS 2027 EPS absolute revision | B6: ='Consensus Bridge'!D8-'Consensus Bridge'!D7 -> -0.02 | C6: 0 | D6: =IF(ABS(B6-'Consensus Bridge'!D9)<=0.000001,"OK","ERROR") -> OK | E6: New minus old | F6: 2026-08-12
A7: MS 2028 EPS absolute revision | B7: ='Consensus Bridge'!E8-'Consensus Bridge'!E7 -> -0.1 | C7: 0 | D7: =IF(ABS(B7-'Consensus Bridge'!E9)<=0.000001,"OK","ERROR") -> OK | E7: New minus old | F7: 2026-08-12
A8: NPG/HDO forecast inclusion | B8: 0 | C8: 0 | D8: =IF(B8=0,"OK","ERROR") -> OK | E8: No forecast uplift booked | F8: 2026-08-12
A9: Citi 2026 EBITDA segment sum | B9: ='Citi Bridge'!B35-'Citi Bridge'!C7 -> 0 | C9: 0 | D9: =IF(ABS(B9)<=C9,"OK","ERROR") -> OK | E9: Segment sum must equal group Figure 3 EBITDA bsi | F9: 2026-08-14
A10: Citi 2027 EBITDA segment sum | B10: ='Citi Bridge'!E35-'Citi Bridge'!D7 -> 0 | C10: 0 | D10: =IF(ABS(B10)<=C10,"OK","ERROR") -> OK | E10: Segment sum must equal group Figure 3 EBITDA bsi | F10: 2026-08-14
A11: Citi 2026 EBITDA bridge sum | B11: ='Citi Bridge'!B48-'Citi Bridge'!C7 -> 0 | C11: 0 | D11: =IF(ABS(B11)<=C11,"OK","ERROR") -> OK | E11: Figure 1 bridge must equal €7,567m | F11: 2026-08-14
A12: Citi 2027 consensus bridge sum | B12: ='Citi Bridge'!B61-7697 -> 0 | C12: 0 | D12: =IF(ABS(B12)<=C12,"OK","ERROR") -> OK | E12: Figure 2 bridge must equal €7,697m | F12: 2026-08-14
A13: Citi 2026 sales segment sum | B13: ='Citi Bridge'!B76-'Citi Bridge'!C6 -> 2 | C13: 2 | D13: =IF(ABS(B13)<=C13,"OK","ERROR") -> OK | E13: €2m rounding tolerance between displayed segment rows and group sales | F13: 2026-08-14
A14: Citi 2027 sales segment sum | B14: ='Citi Bridge'!E76-'Citi Bridge'!D6 -> 1 | C14: 2 | D14: =IF(ABS(B14)<=C14,"OK","ERROR") -> OK | E14: €2m rounding tolerance between displayed segment rows and group sales | F14: 2026-08-14
A15: Formula error scan | B15: 0 | C15: 0 | D15: =IF(B15=0,"OK","ERROR") -> OK | E15: Updated after headless LibreOffice recalc | F15: 2026-09-03
A16: Policy pricing low arithmetic | B16: ='EU Policy Scenario'!B18-562.5 -> 0 | C16: 0 | D16: =IF(ABS(B16)<=C16,"OK","ERROR") -> OK | E16: 10mt × 75% util. × 75% external × €100/t | F16: 2026-09-03
A17: Policy pricing high arithmetic | B17: ='EU Policy Scenario'!C18-600 -> 0 | C17: 0 | D17: =IF(ABS(B17)<=C17,"OK","ERROR") -> OK | E17: 10mt × 75% util. × 80% external × €100/t | F17: 2026-09-03
A18: Europe volume low arithmetic | B18: ='EU Policy Scenario'!B31-8% -> 0 | C18: 0 | D18: =IF(ABS(B18)<=C18,"OK","ERROR") -> OK | E18: 2ppt / 25% base | F18: 2026-09-03
A19: Europe volume high arithmetic | B19: ='EU Policy Scenario'!C31-12% -> 0 | C19: 0 | D19: =IF(ABS(B19)<=C19,"OK","ERROR") -> OK | E19: 3ppt / 25% base | F19: 2026-09-03
A20: Base-case policy uplift excluded | B20: ='EU Policy Scenario'!B51 -> 0 | C20: 0 | D20: =IF(ABS(B20)<=C20,"OK","ERROR") -> OK | E20: No uplift booked | F20: 2026-09-03
