Workbook

Sheet Cover
A1: 化工公司标准模型模板
A2: New period standard: annual 2018A–2025A; quarterly 2024Q1A–2026Q1A; annual forecast 2026E–2028E; quarterly forecast 2026Q2E–2027Q4E
A4: Model identity
A5: Company | B5: [Company]
A6: Ticker | B6: [Ticker]
A7: Currency / unit | B7: RMB mm
A8: Annual history | B8: 2018A–2025A
A9: Quarterly history | B9: 2024Q1A–2026Q1A
A10: Annual forecast | B10: 2026E–2028E
A11: Quarterly forecast | B11: 2026Q2E–2027Q4E
A12: Model date | B12: 2026-07-27
A13: Version | B13: Period-standard v2.0
A15: Critical boundary notes
A16: Annual actuals use annual reports. Standalone Q2/Q3/Q4 consolidated actuals are arithmetic differences of cumulative primary filings; they are not estimates.
A17: Product-series sales volumes include internal use; apparent ASP is a blended proxy. Product-series revenue includes trade and internal-use revenue.
A18: Quarterly product-series costs are not disclosed and remain blank. No quarterly cost allocation is forced.
A19: Historical hardcodes are blue; formulas black; cross-sheet formulas green; forecast assumptions are yellow.
A20: All forecast passthroughs use IF(source="","",source) or equivalent blank gates.
A22: Color convention
A23: Hardcode / actual | B23: Aa123
A24: Formula | B24: Aa123
A25: Cross-sheet formula | B25: Aa123
A26: External link | B26: Aa123
A27: Forecast assumption | B27: Aa123

Sheet Assumptions
A1: Assumptions
A2: Only forecast columns are input-enabled; all are intentionally blank at hand-off.
A4: RMB mm unless stated | B4: 2018A | C4: 2019A | D4: 2020A | E4: 2021A | F4: 2022A | G4: 2023A | H4: 2024A | I4: 2025A | J4: 2024Q1A | K4: 2024Q2A | L4: 2024Q3A | M4: 2024Q4A | N4: 2025Q1A | O4: 2025Q2A | P4: 2025Q3A | Q4: 2025Q4A | R4: 2026Q1A | S4: 2026E | T4: 2027E | U4: 2028E | V4: 2026Q2E | W4: 2026Q3E | X4: 2026Q4E | Y4: 2027Q1E | Z4: 2027Q2E | AA4: 2027Q3E | AB4: 2027Q4E
A5: 聚氨酯系列
A6: Volume growth
A7: Apparent ASP growth
A8: Raw-material share
A9: Non-raw cost inflation
A11: 石化系列
A12: Volume growth
A13: Apparent ASP growth
A14: Raw-material share
A15: Non-raw cost inflation
A17: 精细化学品及新材料系列
A18: Volume growth
... A31: Capex / revenue

Sheet Price Inputs
A1: Price Inputs
A2: Company-disclosed market averages; blanks preserve missing period disclosures.
A4: RMB mm unless stated | B4: 2018A | C4: 2019A | D4: 2020A | E4: 2021A | F4: 2022A | G4: 2023A | H4: 2024A | I4: 2025A | J4: 2024Q1A | K4: 2024Q2A | L4: 2024Q3A | M4: 2024Q4A | N4: 2025Q1A | O4: 2025Q2A | P4: 2025Q3A | Q4: 2025Q4A | R4: 2026Q1A | S4: 2026E | T4: 2027E | U4: 2028E | V4: 2026Q2E | W4: 2026Q3E | X4: 2026Q4E | Y4: 2027Q1E | Z4: 2027Q2E | AA4: 2027Q3E | AB4: 2027Q4E
A5: Polymeric MDI market average (RMB/t; approx.) | S5: =IF(Assumptions!S24="","",Assumptions!S24) | T5: =IF(Assumptions!T24="","",Assumptions!T24) | U5: =IF(Assumptions!U24="","",Assumptions!U24) | V5: =IF(Assumptions!V24="","",Assumptions!V24) | W5: =IF(Assumptions!W24="","",Assumptions!W24) | X5: =IF(Assumptions!X24="","",Assumptions!X24) | Y5: =IF(Assumptions!Y24="","",Assumptions!Y24) | Z5: =IF(Assumptions!Z24="","",Assumptions!Z24) | ... AB5: =IF(Assumptions!AB24="","",Assumptions!AB24)
A6: Pure benzene market average (RMB/t) | S6: =IF(Assumptions!S25="","",Assumptions!S25) | T6: =IF(Assumptions!T25="","",Assumptions!T25) | U6: =IF(Assumptions!U25="","",Assumptions!U25) | V6: =IF(Assumptions!V25="","",Assumptions!V25) | W6: =IF(Assumptions!W25="","",Assumptions!W25) | X6: =IF(Assumptions!X25="","",Assumptions!X25) | Y6: =IF(Assumptions!Y25="","",Assumptions!Y25) | Z6: =IF(Assumptions!Z25="","",Assumptions!Z25) | ... AB6: =IF(Assumptions!AB25="","",Assumptions!AB25)
A7: PMDI − 0.77 × benzene rough spread (RMB/t) | B7: =IF(OR(B5="",B6=""),"",B5-0.77*B6) | C7: =IF(OR(C5="",C6=""),"",C5-0.77*C6) | D7: =IF(OR(D5="",D6=""),"",D5-0.77*D6) | E7: =IF(OR(E5="",E6=""),"",E5-0.77*E6) | F7: =IF(OR(F5="",F6=""),"",F5-0.77*F6) | G7: =IF(OR(G5="",G6=""),"",G5-0.77*G6) | H7: =IF(OR(H5="",H6=""),"",H5-0.77*H6) | I7: =IF(OR(I5="",I6=""),"",I5-0.77*I6) | ... AB7: =IF(OR(AB5="",AB6=""),"",AB5-0.77*AB6)
A8: Disclosure / formula boundary | B8: Template — populate from filing | C8: Template — populate from filing | D8: Template — populate from filing | E8: Template — populate from filing | F8: Template — populate from filing | G8: Template — populate from filing | H8: Template — populate from filing | I8: Template — populate from filing | J8: Template — populate from filing | K8: Template — populate from filing | L8: Template — populate from filing | M8: Template — populate from filing | N8: Template — populate from filing | O8: Template — populate from filing | P8: Template — populate from filing | Q8: Template — populate from filing | R8: Template — populate from filing | S8: Forecast assumption passthrough | T8: Forecast assumption passthrough | U8: Forecast assumption passthrough | V8: Forecast assumption passthrough | W8: Forecast assumption passthrough | X8: Forecast assumption passthrough | Y8: Forecast assumption passthrough | Z8: Forecast assumption passthrough | AA8: Forecast assumption passthrough | AB8: Forecast assumption passthrough

Sheet Volume-Price
A1: Volume-Price
A2: Product-series revenue and volume from filings; apparent ASP uses revenue / disclosed volume.
A4: RMB mm unless stated | B4: 2018A | C4: 2019A | D4: 2020A | E4: 2021A | F4: 2022A | G4: 2023A | H4: 2024A | I4: 2025A | J4: 2024Q1A | K4: 2024Q2A | L4: 2024Q3A | M4: 2024Q4A | N4: 2025Q1A | O4: 2025Q2A | P4: 2025Q3A | Q4: 2025Q4A | R4: 2026Q1A | S4: 2026E | T4: 2027E | U4: 2028E | V4: 2026Q2E | W4: 2026Q3E | X4: 2026Q4E | Y4: 2027Q1E | Z4: 2027Q2E | AA4: 2027Q3E | AB4: 2027Q4E
A5: 聚氨酯系列
A6: Disclosed sales volume (10kt; includes internal use) | S6: =IF(OR(I6="",S10=""),"",I6*(1+S10)) | T6: =IF(OR(S6="",T10=""),"",S6*(1+T10)) | U6: =IF(OR(T6="",U10=""),"",T6*(1+U10)) | V6: =IF(OR(R6="",V10=""),"",R6*(1+V10)) | W6: =IF(OR(V6="",W10=""),"",V6*(1+W10)) | X6: =IF(OR(W6="",X10=""),"",W6*(1+X10)) | Y6: =IF(OR(X6="",Y10=""),"",X6*(1+Y10)) | Z6: =IF(OR(Y6="",Z10=""),"",Y6*(1+Z10)) | AA6: =IF(OR(Z6="",AA10=""),"",Z6*(1+AA10)) | AB6: =IF(OR(AA6="",AB10=""),"",AA6*(1+AB10))
A7: External sales volume (10kt; not disclosed)
A8: Reported product-series revenue
A9: Apparent ASP (RMB/t) | B9: =IFERROR(IF(OR(B6="",B6=0,B8=""),"",B8/B6*100),"") | C9: =IFERROR(IF(OR(C6="",C6=0,C8=""),"",C8/C6*100),"") | D9: =IFERROR(IF(OR(D6="",D6=0,D8=""),"",D8/D6*100),"") | E9: =IFERROR(IF(OR(E6="",E6=0,E8=""),"",E8/E6*100),"") | F9: =IFERROR(IF(OR(F6="",F6=0,F8=""),"",F8/F6*100),"") | G9: =IFERROR(IF(OR(G6="",G6=0,G8=""),"",G8/G6*100),"") | H9: =IFERROR(IF(OR(H6="",H6=0,H8=""),"",H8/H6*100),"") | I9: =IFERROR(IF(OR(I6="",I6=0,I8=""),"",I8/I6*100),"") | ... R9: =IFERROR(IF(OR(R6="",R6=0,R8=""),"",R8/R6*100),"") | S9: =IF(OR(I9="",S11=""),"",I9*(1+S11)) | T9: =IF(OR(S9="",T11=""),"",S9*(1+T11)) | U9: =IF(OR(T9="",U11=""),"",T9*(1+U11)) | V9: =IF(OR(R9="",V11=""),"",R9*(1+V11)) | W9: =IF(OR(V9="",W11=""),"",V9*(1+W11)) | X9: =IF(OR(W9="",X11=""),"",W9*(1+X11)) | Y9: =IF(OR(X9="",Y11=""),"",X9*(1+Y11)) | Z9: =IF(OR(Y9="",Z11=""),"",Y9*(1+Z11)) | AA9: =IF(OR(Z9="",AA11=""),"",Z9*(1+AA11)) | AB9: =IF(OR(AA9="",AB11=""),"",AA9*(1+AB11))
A10: Volume growth | C10: =IFERROR(IF(OR(B6="",B6=0,C6=""),"",C6/B6-1),"") | D10: =IFERROR(IF(OR(C6="",C6=0,D6=""),"",D6/C6-1),"") | E10: =IFERROR(IF(OR(D6="",D6=0,E6=""),"",E6/D6-1),"") | F10: =IFERROR(IF(OR(E6="",E6=0,F6=""),"",F6/E6-1),"") | G10: =IFERROR(IF(OR(F6="",F6=0,G6=""),"",G6/F6-1),"") | H10: =IFERROR(IF(OR(G6="",G6=0,H6=""),"",H6/G6-1),"") | I10: =IFERROR(IF(OR(H6="",H6=0,I6=""),"",I6/H6-1),"") | K10: =IFERROR(IF(OR(J6="",J6=0,K6=""),"",K6/J6-1),"") | L10: =IFERROR(IF(OR(K6="",K6=0,L6=""),"",L6/K6-1),"") | M10: =IFERROR(IF(OR(L6="",L6=0,M6=""),"",M6/L6-1),"") | N10: =IFERROR(IF(OR(M6="",M6=0,N6=""),"",N6/M6-1),"") | O10: =IFERROR(IF(OR(N6="",N6=0,O6=""),"",O6/N6-1),"") | P10: =IFERROR(IF(OR(O6="",O6=0,P6=""),"",P6/O6-1),"") | Q10: =IFERROR(IF(OR(P6="",P6=0,Q6=""),"",Q6/P6-1),"") | R10: =IFERROR(IF(OR(Q6="",Q6=0,R6=""),"",R6/Q6-1),"") | S10: =IF(Assumptions!S6="","",Assumptions!S6) | T10: =IF(Assumptions!T6="","",Assumptions!T6) | U10: =IF(Assumptions!U6="","",Assumptions!U6) | V10: =IF(Assumptions!V6="","",Assumptions!V6) | W10: =IF(Assumptions!W6="","",Assumptions!W6) | X10: =IF(Assumptions!X6="","",Assumptions!X6) | Y10: =IF(Assumptions!Y6="","",Assumptions!Y6) | Z10: =IF(Assumptions!Z6="","",Assumptions!Z6) | ... AB10: =IF(Assumptions!AB6="","",Assumptions!AB6)
A11: Apparent ASP growth | C11: =IFERROR(IF(OR(B9="",B9=0,C9=""),"",C9/B9-1),"") | D11: =IFERROR(IF(OR(C9="",C9=0,D9=""),"",D9/C9-1),"") | E11: =IFERROR(IF(OR(D9="",D9=0,E9=""),"",E9/D9-1),"") | F11: =IFERROR(IF(OR(E9="",E9=0,F9=""),"",F9/E9-1),"") | G11: =IFERROR(IF(OR(F9="",F9=0,G9=""),"",G9/F9-1),"") | H11: =IFERROR(IF(OR(G9="",G9=0,H9=""),"",H9/G9-1),"") | I11: =IFERROR(IF(OR(H9="",H9=0,I9=""),"",I9/H9-1),"") | K11: =IFERROR(IF(OR(J9="",J9=0,K9=""),"",K9/J9-1),"") | L11: =IFERROR(IF(OR(K9="",K9=0,L9=""),"",L9/K9-1),"") | M11: =IFERROR(IF(OR(L9="",L9=0,M9=""),"",M9/L9-1),"") | N11: =IFERROR(IF(OR(M9="",M9=0,N9=""),"",N9/M9-1),"") | O11: =IFERROR(IF(OR(N9="",N9=0,O9=""),"",O9/N9-1),"") | P11: =IFERROR(IF(OR(O9="",O9=0,P9=""),"",P9/O9-1),"") | Q11: =IFERROR(IF(OR(P9="",P9=0,Q9=""),"",Q9/P9-1),"") | R11: =IFERROR(IF(OR(Q9="",Q9=0,R9=""),"",R9/Q9-1),"") | S11: =IF(Assumptions!S7="","",Assumptions!S7) | T11: =IF(Assumptions!T7="","",Assumptions!T7) | U11: =IF(Assumptions!U7="","",Assumptions!U7) | V11: =IF(Assumptions!V7="","",Assumptions!V7) | W11: =IF(Assumptions!W7="","",Assumptions!W7) | X11: =IF(Assumptions!X7="","",Assumptions!X7) | Y11: =IF(Assumptions!Y7="","",Assumptions!Y7) | Z11: =IF(Assumptions!Z7="","",Assumptions!Z7) | ... AB11: =IF(Assumptions!AB7="","",Assumptions!AB7)
A12: Modelled revenue | B12: =IF(B8="","",B8) | C12: =IF(C8="","",C8) | D12: =IF(D8="","",D8) | E12: =IF(E8="","",E8) | F12: =IF(F8="","",F8) | G12: =IF(G8="","",G8) | H12: =IF(H8="","",H8) | I12: =IF(I8="","",I8) | ... R12: =IF(R8="","",R8) | S12: =IF(OR(S6="",S9=""),"",S6*S9/100) | T12: =IF(OR(T6="",T9=""),"",T6*T9/100) | U12: =IF(OR(U6="",U9=""),"",U6*U9/100) | V12: =IF(OR(V6="",V9=""),"",V6*V9/100) | W12: =IF(OR(W6="",W9=""),"",W6*W9/100) | X12: =IF(OR(X6="",X9=""),"",X6*X9/100) | Y12: =IF(OR(Y6="",Y9=""),"",Y6*Y9/100) | Z12: =IF(OR(Z6="",Z9=""),"",Z6*Z9/100) | ... AB12: =IF(OR(AB6="",AB9=""),"",AB6*AB9/100)
A15: 石化系列
A16: Disclosed sales volume (10kt; includes internal use) | S16: =IF(OR(I16="",S20=""),"",I16*(1+S20)) | T16: =IF(OR(S16="",T20=""),"",S16*(1+T20)) | U16: =IF(OR(T16="",U20=""),"",T16*(1+U20)) | V16: =IF(OR(R16="",V20=""),"",R16*(1+V20)) | W16: =IF(OR(V16="",W20=""),"",V16*(1+W20)) | X16: =IF(OR(W16="",X20=""),"",W16*(1+X20)) | Y16: =IF(OR(X16="",Y20=""),"",X16*(1+Y20)) | Z16: =IF(OR(Y16="",Z20=""),"",Y16*(1+Z20)) | AA16: =IF(OR(Z16="",AA20=""),"",Z16*(1+AA20)) | AB16: =IF(OR(AA16="",AB20=""),"",AA16*(1+AB20))
A17: External sales volume (10kt; not disclosed)
A18: Reported product-series revenue
A19: Apparent ASP (RMB/t) | B19: =IFERROR(IF(OR(B16="",B16=0,B18=""),"",B18/B16*100),"") | C19: =IFERROR(IF(OR(C16="",C16=0,C18=""),"",C18/C16*100),"") | D19: =IFERROR(IF(OR(D16="",D16=0,D18=""),"",D18/D16*100),"") | E19: =IFERROR(IF(OR(E16="",E16=0,E18=""),"",E18/E16*100),"") | F19: =IFERROR(IF(OR(F16="",F16=0,F18=""),"",F18/F16*100),"") | G19: =IFERROR(IF(OR(G16="",G16=0,G18=""),"",G18/G16*100),"") | H19: =IFERROR(IF(OR(H16="",H16=0,H18=""),"",H18/H16*100),"") | I19: =IFERROR(IF(OR(I16="",I16=0,I18=""),"",I18/I16*100),"") | ... R19: =IFERROR(IF(OR(R16="",R16=0,R18=""),"",R18/R16*100),"") | S19: =IF(OR(I19="",S21=""),"",I19*(1+S21)) | T19: =IF(OR(S19="",T21=""),"",S19*(1+T21)) | U19: =IF(OR(T19="",U21=""),"",T19*(1+U21)) | V19: =IF(OR(R19="",V21=""),"",R19*(1+V21)) | W19: =IF(OR(V19="",W21=""),"",V19*(1+W21)) | X19: =IF(OR(W19="",X21=""),"",W19*(1+X21)) | Y19: =IF(OR(X19="",Y21=""),"",X19*(1+Y21)) | Z19: =IF(OR(Y19="",Z21=""),"",Y19*(1+Z21)) | AA19: =IF(OR(Z19="",AA21=""),"",Z19*(1+AA21)) | AB19: =IF(OR(AA19="",AB21=""),"",AA19*(1+AB21))
A20: Volume growth | C20: =IFERROR(IF(OR(B16="",B16=0,C16=""),"",C16/B16-1),"") | D20: =IFERROR(IF(OR(C16="",C16=0,D16=""),"",D16/C16-1),"") | E20: =IFERROR(IF(OR(D16="",D16=0,E16=""),"",E16/D16-1),"") | F20: =IFERROR(IF(OR(E16="",E16=0,F16=""),"",F16/E16-1),"") | G20: =IFERROR(IF(OR(F16="",F16=0,G16=""),"",G16/F16-1),"") | H20: =IFERROR(IF(OR(G16="",G16=0,H16=""),"",H16/G16-1),"") | I20: =IFERROR(IF(OR(H16="",H16=0,I16=""),"",I16/H16-1),"") | K20: =IFERROR(IF(OR(J16="",J16=0,K16=""),"",K16/J16-1),"") | L20: =IFERROR(IF(OR(K16="",K16=0,L16=""),"",L16/K16-1),"") | M20: =IFERROR(IF(OR(L16="",L16=0,M16=""),"",M16/L16-1),"") | N20: =IFERROR(IF(OR(M16="",M16=0,N16=""),"",N16/M16-1),"") | O20: =IFERROR(IF(OR(N16="",N16=0,O16=""),"",O16/N16-1),"") | P20: =IFERROR(IF(OR(O16="",O16=0,P16=""),"",P16/O16-1),"") | Q20: =IFERROR(IF(OR(P16="",P16=0,Q16=""),"",Q16/P16-1),"") | R20: =IFERROR(IF(OR(Q16="",Q16=0,R16=""),"",R16/Q16-1),"") | S20: =IF(Assumptions!S12="","",Assumptions!S12) | T20: =IF(Assumptions!T12="","",Assumptions!T12) | U20: =IF(Assumptions!U12="","",Assumptions!U12) | V20: =IF(Assumptions!V12="","",Assumptions!V12) | W20: =IF(Assumptions!W12="","",Assumptions!W12) | X20: =IF(Assumptions!X12="","",Assumptions!X12) | Y20: =IF(Assumptions!Y12="","",Assumptions!Y12) | Z20: =IF(Assumptions!Z12="","",Assumptions!Z12) | ... AB20: =IF(Assumptions!AB12="","",Assumptions!AB12)
A21: Apparent ASP growth | C21: =IFERROR(IF(OR(B19="",B19=0,C19=""),"",C19/B19-1),"") | D21: =IFERROR(IF(OR(C19="",C19=0,D19=""),"",D19/C19-1),"") | E21: =IFERROR(IF(OR(D19="",D19=0,E19=""),"",E19/D19-1),"") | F21: =IFERROR(IF(OR(E19="",E19=0,F19=""),"",F19/E19-1),"") | G21: =IFERROR(IF(OR(F19="",F19=0,G19=""),"",G19/F19-1),"") | H21: =IFERROR(IF(OR(G19="",G19=0,H19=""),"",H19/G19-1),"") | I21: =IFERROR(IF(OR(H19="",H19=0,I19=""),"",I19/H19-1),"") | K21: =IFERROR(IF(OR(J19="",J19=0,K19=""),"",K19/J19-1),"") | L21: =IFERROR(IF(OR(K19="",K19=0,L19=""),"",L19/K19-1),"") | M21: =IFERROR(IF(OR(L19="",L19=0,M19=""),"",M19/L19-1),"") | N21: =IFERROR(IF(OR(M19="",M19=0,N19=""),"",N19/M19-1),"") | O21: =IFERROR(IF(OR(N19="",N19=0,O19=""),"",O19/N19-1),"") | P21: =IFERROR(IF(OR(O19="",O19=0,P19=""),"",P19/O19-1),"") | Q21: =IFERROR(IF(OR(P19="",P19=0,Q19=""),"",Q19/P19-1),"") | R21: =IFERROR(IF(OR(Q19="",Q19=0,R19=""),"",R19/Q19-1),"") | S21: =IF(Assumptions!S13="","",Assumptions!S13) | T21: =IF(Assumptions!T13="","",Assumptions!T13) | U21: =IF(Assumptions!U13="","",Assumptions!U13) | V21: =IF(Assumptions!V13="","",Assumptions!V13) | W21: =IF(Assumptions!W13="","",Assumptions!W13) | X21: =IF(Assumptions!X13="","",Assumptions!X13) | Y21: =IF(Assumptions!Y13="","",Assumptions!Y13) | Z21: =IF(Assumptions!Z13="","",Assumptions!Z13) | ... AB21: =IF(Assumptions!AB13="","",Assumptions!AB13)
A22: Modelled revenue | B22: =IF(B18="","",B18) | C22: =IF(C18="","",C18) | D22: =IF(D18="","",D18) | E22: =IF(E18="","",E18) | F22: =IF(F18="","",F18) | G22: =IF(G18="","",G18) | H22: =IF(H18="","",H18) | I22: =IF(I18="","",I18) | ... R22: =IF(R18="","",R18) | S22: =IF(OR(S16="",S19=""),"",S16*S19/100) | T22: =IF(OR(T16="",T19=""),"",T16*T19/100) | U22: =IF(OR(U16="",U19=""),"",U16*U19/100) | V22: =IF(OR(V16="",V19=""),"",V16*V19/100) | W22: =IF(OR(W16="",W19=""),"",W16*W19/100) | X22: =IF(OR(X16="",X19=""),"",X16*X19/100) | Y22: =IF(OR(Y16="",Y19=""),"",Y16*Y19/100) | Z22: =IF(OR(Z16="",Z19=""),"",Z16*Z19/100) | ... AB22: =IF(OR(AB16="",AB19=""),"",AB16*AB19/100)
A25: 精细化学品及新材料系列
A26: Disclosed sales volume (10kt; includes internal use) | S26: =IF(OR(I26="",S30=""),"",I26*(1+S30)) | T26: =IF(OR(S26="",T30=""),"",S26*(1+T30)) | U26: =IF(OR(T26="",U30=""),"",T26*(1+U30)) | V26: =IF(OR(R26="",V30=""),"",R26*(1+V30)) | W26: =IF(OR(V26="",W30=""),"",V26*(1+W30)) | X26: =IF(OR(W26="",X30=""),"",W26*(1+X30)) | Y26: =IF(OR(X26="",Y30=""),"",X26*(1+Y30)) | Z26: =IF(OR(Y26="",Z30=""),"",Y26*(1+Z30)) | AA26: =IF(OR(Z26="",AA30=""),"",Z26*(1+AA30)) | AB26: =IF(OR(AA26="",AB30=""),"",AA26*(1+AB30))
A27: External sales volume (10kt; not disclosed)
A28: Reported product-series revenue
A29: Apparent ASP (RMB/t) | B29: =IFERROR(IF(OR(B26="",B26=0,B28=""),"",B28/B26*100),"") | C29: =IFERROR(IF(OR(C26="",C26=0,C28=""),"",C28/C26*100),"") | D29: =IFERROR(IF(OR(D26="",D26=0,D28=""),"",D28/D26*100),"") | E29: =IFERROR(IF(OR(E26="",E26=0,E28=""),"",E28/E26*100),"") | F29: =IFERROR(IF(OR(F26="",F26=0,F28=""),"",F28/F26*100),"") | G29: =IFERROR(IF(OR(G26="",G26=0,G28=""),"",G28/G26*100),"") | H29: =IFERROR(IF(OR(H26="",H26=0,H28=""),"",H28/H26*100),"") | I29: =IFERROR(IF(OR(I26="",I26=0,I28=""),"",I28/I26*100),"") | ... R29: =IFERROR(IF(OR(R26="",R26=0,R28=""),"",R28/R26*100),"") | S29: =IF(OR(I29="",S31=""),"",I29*(1+S31)) | T29: =IF(OR(S29="",T31=""),"",S29*(1+T31)) | U29: =IF(OR(T29="",U31=""),"",T29*(1+U31)) | V29: =IF(OR(R29="",V31=""),"",R29*(1+V31)) | W29: =IF(OR(V29="",W31=""),"",V29*(1+W31)) | X29: =IF(OR(W29="",X31=""),"",W29*(1+X31)) | Y29: =IF(OR(X29="",Y31=""),"",X29*(1+Y31)) | Z29: =IF(OR(Y29="",Z31=""),"",Y29*(1+Z31)) | AA29: =IF(OR(Z29="",AA31=""),"",Z29*(1+AA31)) | AB29: =IF(OR(AA29="",AB31=""),"",AA29*(1+AB31))
A30: Volume growth | C30: =IFERROR(IF(OR(B26="",B26=0,C26=""),"",C26/B26-1),"") | D30: =IFERROR(IF(OR(C26="",C26=0,D26=""),"",D26/C26-1),"") | E30: =IFERROR(IF(OR(D26="",D26=0,E26=""),"",E26/D26-1),"") | F30: =IFERROR(IF(OR(E26="",E26=0,F26=""),"",F26/E26-1),"") | G30: =IFERROR(IF(OR(F26="",F26=0,G26=""),"",G26/F26-1),"") | H30: =IFERROR(IF(OR(G26="",G26=0,H26=""),"",H26/G26-1),"") | I30: =IFERROR(IF(OR(H26="",H26=0,I26=""),"",I26/H26-1),"") | K30: =IFERROR(IF(OR(J26="",J26=0,K26=""),"",K26/J26-1),"") | L30: =IFERROR(IF(OR(K26="",K26=0,L26=""),"",L26/K26-1),"") | M30: =IFERROR(IF(OR(L26="",L26=0,M26=""),"",M26/L26-1),"") | N30: =IFERROR(IF(OR(M26="",M26=0,N26=""),"",N26/M26-1),"") | O30: =IFERROR(IF(OR(N26="",N26=0,O26=""),"",O26/N26-1),"") | P30: =IFERROR(IF(OR(O26="",O26=0,P26=""),"",P26/O26-1),"") | Q30: =IFERROR(IF(OR(P26="",P26=0,Q26=""),"",Q26/P26-1),"") | R30: =IFERROR(IF(OR(Q26="",Q26=0,R26=""),"",R26/Q26-1),"") | S30: =IF(Assumptions!S18="","",Assumptions!S18) | T30: =IF(Assumptions!T18="","",Assumptions!T18) | U30: =IF(Assumptions!U18="","",Assumptions!U18) | V30: =IF(Assumptions!V18="","",Assumptions!V18) | W30: =IF(Assumptions!W18="","",Assumptions!W18) | X30: =IF(Assumptions!X18="","",Assumptions!X18) | Y30: =IF(Assumptions!Y18="","",Assumptions!Y18) | Z30: =IF(Assumptions!Z18="","",Assumptions!Z18) | ... AB30: =IF(Assumptions!AB18="","",Assumptions!AB18)
A31: Apparent ASP growth | C31: =IFERROR(IF(OR(B29="",B29=0,C29=""),"",C29/B29-1),"") | D31: =IFERROR(IF(OR(C29="",C29=0,D29=""),"",D29/C29-1),"") | E31: =IFERROR(IF(OR(D29="",D29=0,E29=""),"",E29/D29-1),"") | F31: =IFERROR(IF(OR(E29="",E29=0,F29=""),"",F29/E29-1),"") | G31: =IFERROR(IF(OR(F29="",F29=0,G29=""),"",G29/F29-1),"") | H31: =IFERROR(IF(OR(G29="",G29=0,H29=""),"",H29/G29-1),"") | I31: =IFERROR(IF(OR(H29="",H29=0,I29=""),"",I29/H29-1),"") | K31: =IFERROR(IF(OR(J29="",J29=0,K29=""),"",K29/J29-1),"") | L31: =IFERROR(IF(OR(K29="",K29=0,L29=""),"",L29/K29-1),"") | M31: =IFERROR(IF(OR(L29="",L29=0,M29=""),"",M29/L29-1),"") | N31: =IFERROR(IF(OR(M29="",M29=0,N29=""),"",N29/M29-1),"") | O31: =IFERROR(IF(OR(N29="",N29=0,O29=""),"",O29/N29-1),"") | P31: =IFERROR(IF(OR(O29="",O29=0,P29=""),"",P29/O29-1),"") | Q31: =IFERROR(IF(OR(P29="",P29=0,Q29=""),"",Q29/P29-1),"") | R31: =IFERROR(IF(OR(Q29="",Q29=0,R29=""),"",R29/Q29-1),"") | S31: =IF(Assumptions!S19="","",Assumptions!S19) | T31: =IF(Assumptions!T19="","",Assumptions!T19) | U31: =IF(Assumptions!U19="","",Assumptions!U19) | V31: =IF(Assumptions!V19="","",Assumptions!V19) | W31: =IF(Assumptions!W19="","",Assumptions!W19) | X31: =IF(Assumptions!X19="","",Assumptions!X19) | Y31: =IF(Assumptions!Y19="","",Assumptions!Y19) | Z31: =IF(Assumptions!Z19="","",Assumptions!Z19) | ... AB31: =IF(Assumptions!AB19="","",Assumptions!AB19)
A32: Modelled revenue | B32: =IF(B28="","",B28) | C32: =IF(C28="","",C28) | D32: =IF(D28="","",D28) | E32: =IF(E28="","",E28) | F32: =IF(F28="","",F28) | G32: =IF(G28="","",G28) | H32: =IF(H28="","",H28) | I32: =IF(I28="","",I28) | ... R32: =IF(R28="","",R28) | S32: =IF(OR(S26="",S29=""),"",S26*S29/100) | T32: =IF(OR(T26="",T29=""),"",T26*T29/100) | U32: =IF(OR(U26="",U29=""),"",U26*U29/100) | V32: =IF(OR(V26="",V29=""),"",V26*V29/100) | W32: =IF(OR(W26="",W29=""),"",W26*W29/100) | X32: =IF(OR(X26="",X29=""),"",X26*X29/100) | Y32: =IF(OR(Y26="",Y29=""),"",Y26*Y29/100) | Z32: =IF(OR(Z26="",Z29=""),"",Z26*Z29/100) | ... AB32: =IF(OR(AB26="",AB29=""),"",AB26*AB29/100)

Sheet Cost Bridge
A1: Cost Bridge
A2: Annual segment costs and raw-material shares are filing actuals; quarterly segment costs are intentionally blank.
A4: RMB mm unless stated | B4: 2018A | C4: 2019A | D4: 2020A | E4: 2021A | F4: 2022A | G4: 2023A | H4: 2024A | I4: 2025A | J4: 2024Q1A | K4: 2024Q2A | L4: 2024Q3A | M4: 2024Q4A | N4: 2025Q1A | O4: 2025Q2A | P4: 2025Q3A | Q4: 2025Q4A | R4: 2026Q1A | S4: 2026E | T4: 2027E | U4: 2028E | V4: 2026Q2E | W4: 2026Q3E | X4: 2026Q4E | Y4: 2027Q1E | Z4: 2027Q2E | AA4: 2027Q3E | AB4: 2027Q4E
A5: 聚氨酯系列
A6: Disclosed sales volume (10kt) | B6: ='Volume-Price'!B6 -> 0 | C6: ='Volume-Price'!C6 -> 0 | D6: ='Volume-Price'!D6 -> 0 | E6: ='Volume-Price'!E6 -> 0 | F6: ='Volume-Price'!F6 -> 0 | G6: ='Volume-Price'!G6 -> 0 | H6: ='Volume-Price'!H6 -> 0 | I6: ='Volume-Price'!I6 -> 0 | ... AB6: ='Volume-Price'!AB6
A7: Reported product-series cost
A8: Unit cost proxy (RMB/t) | B8: =IFERROR(IF(OR(B6="",B6=0,B7=""),"",B7/B6*100),"") | C8: =IFERROR(IF(OR(C6="",C6=0,C7=""),"",C7/C6*100),"") | D8: =IFERROR(IF(OR(D6="",D6=0,D7=""),"",D7/D6*100),"") | E8: =IFERROR(IF(OR(E6="",E6=0,E7=""),"",E7/E6*100),"") | F8: =IFERROR(IF(OR(F6="",F6=0,F7=""),"",F7/F6*100),"") | G8: =IFERROR(IF(OR(G6="",G6=0,G7=""),"",G7/G6*100),"") | H8: =IFERROR(IF(OR(H6="",H6=0,H7=""),"",H7/H6*100),"") | I8: =IFERROR(IF(OR(I6="",I6=0,I7=""),"",I7/I6*100),"") | ... AB8: =IFERROR(IF(OR(AB6="",AB6=0,AB7=""),"",AB7/AB6*100),"")
A9: Raw-material share of product-series cost | S9: =IF(Assumptions!S8="","",Assumptions!S8) | T9: =IF(Assumptions!T8="","",Assumptions!T8) | U9: =IF(Assumptions!U8="","",Assumptions!U8) | V9: =IF(Assumptions!V8="","",Assumptions!V8) | W9: =IF(Assumptions!W8="","",Assumptions!W8) | X9: =IF(Assumptions!X8="","",Assumptions!X8) | Y9: =IF(Assumptions!Y8="","",Assumptions!Y8) | Z9: =IF(Assumptions!Z8="","",Assumptions!Z8) | ... AB9: =IF(Assumptions!AB8="","",Assumptions!AB8)
A10: Raw price index (2025A benzene = 1.00x) | B10: =IFERROR(IF(OR('Price Inputs'!B$6="",'Price Inputs'!$I$6=""),"",'Price Inputs'!B$6/'Price Inputs'!$I$6),"") | C10: =IFERROR(IF(OR('Price Inputs'!C$6="",'Price Inputs'!$I$6=""),"",'Price Inputs'!C$6/'Price Inputs'!$I$6),"") | D10: =IFERROR(IF(OR('Price Inputs'!D$6="",'Price Inputs'!$I$6=""),"",'Price Inputs'!D$6/'Price Inputs'!$I$6),"") | E10: =IFERROR(IF(OR('Price Inputs'!E$6="",'Price Inputs'!$I$6=""),"",'Price Inputs'!E$6/'Price Inputs'!$I$6),"") | F10: =IFERROR(IF(OR('Price Inputs'!F$6="",'Price Inputs'!$I$6=""),"",'Price Inputs'!F$6/'Price Inputs'!$I$6),"") | G10: =IFERROR(IF(OR('Price Inputs'!G$6="",'Price Inputs'!$I$6=""),"",'Price Inputs'!G$6/'Price Inputs'!$I$6),"") | H10: =IFERROR(IF(OR('Price Inputs'!H$6="",'Price Inputs'!$I$6=""),"",'Price Inputs'!H$6/'Price Inputs'!$I$6),"") | I10: =IFERROR(IF(OR('Price Inputs'!I$6="",'Price Inputs'!$I$6=""),"",'Price Inputs'!I$6/'Price Inputs'!$I$6),"") | ... AB10: =IFERROR(IF(OR('Price Inputs'!AB$6="",'Price Inputs'!$I$6=""),"",'Price Inputs'!AB$6/'Price Inputs'!$I$6),"")
A11: Non-raw cost index | B11: =IF(B8="","",1) | C11: =IF(C8="","",1) | D11: =IF(D8="","",1) | E11: =IF(E8="","",1) | F11: =IF(F8="","",1) | G11: =IF(G8="","",1) | H11: =IF(H8="","",1) | I11: =IF(I8="","",1) | ... R11: =IF(R8="","",1) | S11: =IF(Assumptions!S9="","",1*(1+Assumptions!S9)) | T11: =IF(Assumptions!T9="","",S11*(1+Assumptions!T9)) | U11: =IF(Assumptions!U9="","",T11*(1+Assumptions!U9)) | V11: =IF(Assumptions!V9="","",1*(1+Assumptions!V9)) | W11: =IF(Assumptions!W9="","",V11*(1+Assumptions!W9)) | X11: =IF(Assumptions!X9="","",W11*(1+Assumptions!X9)) | Y11: =IF(Assumptions!Y9="","",X11*(1+Assumptions!Y9)) | Z11: =IF(Assumptions!Z9="","",Y11*(1+Assumptions!Z9)) | AA11: =IF(Assumptions!AA9="","",Z11*(1+Assumptions!AA9)) | AB11: =IF(Assumptions!AB9="","",AA11*(1+Assumptions!AB9))
A12: Forecast unit cost (RMB/t) | B12: =IF(B8="","",B8) | C12: =IF(C8="","",C8) | D12: =IF(D8="","",D8) | E12: =IF(E8="","",E8) | F12: =IF(F8="","",F8) | G12: =IF(G8="","",G8) | H12: =IF(H8="","",H8) | I12: =IF(I8="","",I8) | ... R12: =IF(R8="","",R8) | S12: =IF(OR($I$8="",S9="",S10="",S11=""),"",$I$8*(S9*S10+(1-S9)*S11)) | T12: =IF(OR($I$8="",T9="",T10="",T11=""),"",$I$8*(T9*T10+(1-T9)*T11)) | U12: =IF(OR($I$8="",U9="",U10="",U11=""),"",$I$8*(U9*U10+(1-U9)*U11)) | V12: =IF(OR($I$8="",V9="",V10="",V11=""),"",$I$8*(V9*V10+(1-V9)*V11)) | W12: =IF(OR($I$8="",W9="",W10="",W11=""),"",$I$8*(W9*W10+(1-W9)*W11)) | X12: =IF(OR($I$8="",X9="",X10="",X11=""),"",$I$8*(X9*X10+(1-X9)*X11)) | Y12: =IF(OR($I$8="",Y9="",Y10="",Y11=""),"",$I$8*(Y9*Y10+(1-Y9)*Y11)) | Z12: =IF(OR($I$8="",Z9="",Z10="",Z11=""),"",$I$8*(Z9*Z10+(1-Z9)*Z11)) | ... AB12: =IF(OR($I$8="",AB9="",AB10="",AB11=""),"",$I$8*(AB9*AB10+(1-AB9)*AB11))
A13: Modelled product-series cost | B13: =IF(B7="","",B7) | C13: =IF(C7="","",C7) | D13: =IF(D7="","",D7) | E13: =IF(E7="","",E7) | F13: =IF(F7="","",F7) | G13: =IF(G7="","",G7) | H13: =IF(H7="","",H7) | I13: =IF(I7="","",I7) | ... R13: =IF(R7="","",R7) | S13: =IF(OR(S6="",S12=""),"",S6*S12/100) | T13: =IF(OR(T6="",T12=""),"",T6*T12/100) | U13: =IF(OR(U6="",U12=""),"",U6*U12/100) | V13: =IF(OR(V6="",V12=""),"",V6*V12/100) | W13: =IF(OR(W6="",W12=""),"",W6*W12/100) | X13: =IF(OR(X6="",X12=""),"",X6*X12/100) | Y13: =IF(OR(Y6="",Y12=""),"",Y6*Y12/100) | Z13: =IF(OR(Z6="",Z12=""),"",Z6*Z12/100) | ... AB13: =IF(OR(AB6="",AB12=""),"",AB6*AB12/100)
A16: 石化系列
A17: Disclosed sales volume (10kt) | B17: ='Volume-Price'!B16 -> 0 | C17: ='Volume-Price'!C16 -> 0 | D17: ='Volume-Price'!D16 -> 0 | E17: ='Volume-Price'!E16 -> 0 | F17: ='Volume-Price'!F16 -> 0 | G17: ='Volume-Price'!G16 -> 0 | H17: ='Volume-Price'!H16 -> 0 | I17: ='Volume-Price'!I16 -> 0 | ... AB17: ='Volume-Price'!AB16
A18: Reported product-series cost
A19: Unit cost proxy (RMB/t) | B19: =IFERROR(IF(OR(B17="",B17=0,B18=""),"",B18/B17*100),"") | C19: =IFERROR(IF(OR(C17="",C17=0,C18=""),"",C18/C17*100),"") | D19: =IFERROR(IF(OR(D17="",D17=0,D18=""),"",D18/D17*100),"") | E19: =IFERROR(IF(OR(E17="",E17=0,E18=""),"",E18/E17*100),"") | F19: =IFERROR(IF(OR(F17="",F17=0,F18=""),"",F18/F17*100),"") | G19: =IFERROR(IF(OR(G17="",G17=0,G18=""),"",G18/G17*100),"") | H19: =IFERROR(IF(OR(H17="",H17=0,H18=""),"",H18/H17*100),"") | I19: =IFERROR(IF(OR(I17="",I17=0,I18=""),"",I18/I17*100),"") | ... AB19: =IFERROR(IF(OR(AB17="",AB17=0,AB18=""),"",AB18/AB17*100),"")
A20: Raw-material share of product-series cost | S20: =IF(Assumptions!S14="","",Assumptions!S14) | T20: =IF(Assumptions!T14="","",Assumptions!T14) | U20: =IF(Assumptions!U14="","",Assumptions!U14) | V20: =IF(Assumptions!V14="","",Assumptions!V14) | W20: =IF(Assumptions!W14="","",Assumptions!W14) | X20: =IF(Assumptions!X14="","",Assumptions!X14) | Y20: =IF(Assumptions!Y14="","",Assumptions!Y14) | Z20: =IF(Assumptions!Z14="","",Assumptions!Z14) | ... AB20: =IF(Assumptions!AB14="","",Assumptions!AB14)
A21: Raw price index (2025A benzene = 1.00x) | B21: =IFERROR(IF(OR('Price Inputs'!B$6="",'Price Inputs'!$I$6=""),"",'Price Inputs'!B$6/'Price Inputs'!$I$6),"") | C21: =IFERROR(IF(OR('Price Inputs'!C$6="",'Price Inputs'!$I$6=""),"",'Price Inputs'!C$6/'Price Inputs'!$I$6),"") | D21: =IFERROR(IF(OR('Price Inputs'!D$6="",'Price Inputs'!$I$6=""),"",'Price Inputs'!D$6/'Price Inputs'!$I$6),"") | E21: =IFERROR(IF(OR('Price Inputs'!E$6="",'Price Inputs'!$I$6=""),"",'Price Inputs'!E$6/'Price Inputs'!$I$6),"") | F21: =IFERROR(IF(OR('Price Inputs'!F$6="",'Price Inputs'!$I$6=""),"",'Price Inputs'!F$6/'Price Inputs'!$I$6),"") | G21: =IFERROR(IF(OR('Price Inputs'!G$6="",'Price Inputs'!$I$6=""),"",'Price Inputs'!G$6/'Price Inputs'!$I$6),"") | H21: =IFERROR(IF(OR('Price Inputs'!H$6="",'Price Inputs'!$I$6=""),"",'Price Inputs'!H$6/'Price Inputs'!$I$6),"") | I21: =IFERROR(IF(OR('Price Inputs'!I$6="",'Price Inputs'!$I$6=""),"",'Price Inputs'!I$6/'Price Inputs'!$I$6),"") | ... AB21: =IFERROR(IF(OR('Price Inputs'!AB$6="",'Price Inputs'!$I$6=""),"",'Price Inputs'!AB$6/'Price Inputs'!$I$6),"")
A22: Non-raw cost index | B22: =IF(B19="","",1) | C22: =IF(C19="","",1) | D22: =IF(D19="","",1) | E22: =IF(E19="","",1) | F22: =IF(F19="","",1) | G22: =IF(G19="","",1) | H22: =IF(H19="","",1) | I22: =IF(I19="","",1) | ... R22: =IF(R19="","",1) | S22: =IF(Assumptions!S15="","",1*(1+Assumptions!S15)) | T22: =IF(Assumptions!T15="","",S22*(1+Assumptions!T15)) | U22: =IF(Assumptions!U15="","",T22*(1+Assumptions!U15)) | V22: =IF(Assumptions!V15="","",1*(1+Assumptions!V15)) | W22: =IF(Assumptions!W15="","",V22*(1+Assumptions!W15)) | X22: =IF(Assumptions!X15="","",W22*(1+Assumptions!X15)) | Y22: =IF(Assumptions!Y15="","",X22*(1+Assumptions!Y15)) | Z22: =IF(Assumptions!Z15="","",Y22*(1+Assumptions!Z15)) | AA22: =IF(Assumptions!AA15="","",Z22*(1+Assumptions!AA15)) | AB22: =IF(Assumptions!AB15="","",AA22*(1+Assumptions!AB15))
A23: Forecast unit cost (RMB/t) | B23: =IF(B19="","",B19) | C23: =IF(C19="","",C19) | D23: =IF(D19="","",D19) | E23: =IF(E19="","",E19) | F23: =IF(F19="","",F19) | G23: =IF(G19="","",G19) | H23: =IF(H19="","",H19) | I23: =IF(I19="","",I19) | ... R23: =IF(R19="","",R19) | S23: =IF(OR($I$19="",S20="",S21="",S22=""),"",$I$19*(S20*S21+(1-S20)*S22)) | T23: =IF(OR($I$19="",T20="",T21="",T22=""),"",$I$19*(T20*T21+(1-T20)*T22)) | U23: =IF(OR($I$19="",U20="",U21="",U22=""),"",$I$19*(U20*U21+(1-U20)*U22)) | V23: =IF(OR($I$19="",V20="",V21="",V22=""),"",$I$19*(V20*V21+(1-V20)*V22)) | W23: =IF(OR($I$19="",W20="",W21="",W22=""),"",$I$19*(W20*W21+(1-W20)*W22)) | X23: =IF(OR($I$19="",X20="",X21="",X22=""),"",$I$19*(X20*X21+(1-X20)*X22)) | Y23: =IF(OR($I$19="",Y20="",Y21="",Y22=""),"",$I$19*(Y20*Y21+(1-Y20)*Y22)) | Z23: =IF(OR($I$19="",Z20="",Z21="",Z22=""),"",$I$19*(Z20*Z21+(1-Z20)*Z22)) | ... AB23: =IF(OR($I$19="",AB20="",AB21="",AB22=""),"",$I$19*(AB20*AB21+(1-AB20)*AB22))
A24: Modelled product-series cost | B24: =IF(B18="","",B18) | C24: =IF(C18="","",C18) | D24: =IF(D18="","",D18) | E24: =IF(E18="","",E18) | F24: =IF(F18="","",F18) | G24: =IF(G18="","",G18) | H24: =IF(H18="","",H18) | I24: =IF(I18="","",I18) | ... R24: =IF(R18="","",R18) | S24: =IF(OR(S17="",S23=""),"",S17*S23/100) | T24: =IF(OR(T17="",T23=""),"",T17*T23/100) | U24: =IF(OR(U17="",U23=""),"",U17*U23/100) | V24: =IF(OR(V17="",V23=""),"",V17*V23/100) | W24: =IF(OR(W17="",W23=""),"",W17*W23/100) | X24: =IF(OR(X17="",X23=""),"",X17*X23/100) | Y24: =IF(OR(Y17="",Y23=""),"",Y17*Y23/100) | Z24: =IF(OR(Z17="",Z23=""),"",Z17*Z23/100) | ... AB24: =IF(OR(AB17="",AB23=""),"",AB17*AB23/100)
A27: 精细化学品及新材料系列
A28: Disclosed sales volume (10kt) | B28: ='Volume-Price'!B26 -> 0 | C28: ='Volume-Price'!C26 -> 0 | D28: ='Volume-Price'!D26 -> 0 | E28: ='Volume-Price'!E26 -> 0 | F28: ='Volume-Price'!F26 -> 0 | G28: ='Volume-Price'!G26 -> 0 | H28: ='Volume-Price'!H26 -> 0 | I28: ='Volume-Price'!I26 -> 0 | ... AB28: ='Volume-Price'!AB26
A29: Reported product-series cost
A30: Unit cost proxy (RMB/t) | B30: =IFERROR(IF(OR(B28="",B28=0,B29=""),"",B29/B28*100),"") | C30: =IFERROR(IF(OR(C28="",C28=0,C29=""),"",C29/C28*100),"") | D30: =IFERROR(IF(OR(D28="",D28=0,D29=""),"",D29/D28*100),"") | E30: =IFERROR(IF(OR(E28="",E28=0,E29=""),"",E29/E28*100),"") | F30: =IFERROR(IF(OR(F28="",F28=0,F29=""),"",F29/F28*100),"") | G30: =IFERROR(IF(OR(G28="",G28=0,G29=""),"",G29/G28*100),"") | H30: =IFERROR(IF(OR(H28="",H28=0,H29=""),"",H29/H28*100),"") | I30: =IFERROR(IF(OR(I28="",I28=0,I29=""),"",I29/I28*100),"") | ... AB30: =IFERROR(IF(OR(AB28="",AB28=0,AB29=""),"",AB29/AB28*100),"")
A31: Raw-material share of product-series cost | S31: =IF(Assumptions!S20="","",Assumptions!S20) | T31: =IF(Assumptions!T20="","",Assumptions!T20) | U31: =IF(Assumptions!U20="","",Assumptions!U20) | V31: =IF(Assumptions!V20="","",Assumptions!V20) | W31: =IF(Assumptions!W20="","",Assumptions!W20) | X31: =IF(Assumptions!X20="","",Assumptions!X20) | Y31: =IF(Assumptions!Y20="","",Assumptions!Y20) | Z31: =IF(Assumptions!Z20="","",Assumptions!Z20) | ... AB31: =IF(Assumptions!AB20="","",Assumptions!AB20)
A32: Raw price index (2025A benzene = 1.00x) | B32: =IFERROR(IF(OR('Price Inputs'!B$6="",'Price Inputs'!$I$6=""),"",'Price Inputs'!B$6/'Price Inputs'!$I$6),"") | C32: =IFERROR(IF(OR('Price Inputs'!C$6="",'Price Inputs'!$I$6=""),"",'Price Inputs'!C$6/'Price Inputs'!$I$6),"") | D32: =IFERROR(IF(OR('Price Inputs'!D$6="",'Price Inputs'!$I$6=""),"",'Price Inputs'!D$6/'Price Inputs'!$I$6),"") | E32: =IFERROR(IF(OR('Price Inputs'!E$6="",'Price Inputs'!$I$6=""),"",'Price Inputs'!E$6/'Price Inputs'!$I$6),"") | F32: =IFERROR(IF(OR('Price Inputs'!F$6="",'Price Inputs'!$I$6=""),"",'Price Inputs'!F$6/'Price Inputs'!$I$6),"") | G32: =IFERROR(IF(OR('Price Inputs'!G$6="",'Price Inputs'!$I$6=""),"",'Price Inputs'!G$6/'Price Inputs'!$I$6),"") | H32: =IFERROR(IF(OR('Price Inputs'!H$6="",'Price Inputs'!$I$6=""),"",'Price Inputs'!H$6/'Price Inputs'!$I$6),"") | I32: =IFERROR(IF(OR('Price Inputs'!I$6="",'Price Inputs'!$I$6=""),"",'Price Inputs'!I$6/'Price Inputs'!$I$6),"") | ... AB32: =IFERROR(IF(OR('Price Inputs'!AB$6="",'Price Inputs'!$I$6=""),"",'Price Inputs'!AB$6/'Price Inputs'!$I$6),"")
A33: Non-raw cost index | B33: =IF(B30="","",1) | C33: =IF(C30="","",1) | D33: =IF(D30="","",1) | E33: =IF(E30="","",1) | F33: =IF(F30="","",1) | G33: =IF(G30="","",1) | H33: =IF(H30="","",1) | I33: =IF(I30="","",1) | ... R33: =IF(R30="","",1) | S33: =IF(Assumptions!S21="","",1*(1+Assumptions!S21)) | T33: =IF(Assumptions!T21="","",S33*(1+Assumptions!T21)) | U33: =IF(Assumptions!U21="","",T33*(1+Assumptions!U21)) | V33: =IF(Assumptions!V21="","",1*(1+Assumptions!V21)) | W33: =IF(Assumptions!W21="","",V33*(1+Assumptions!W21)) | X33: =IF(Assumptions!X21="","",W33*(1+Assumptions!X21)) | Y33: =IF(Assumptions!Y21="","",X33*(1+Assumptions!Y21)) | Z33: =IF(Assumptions!Z21="","",Y33*(1+Assumptions!Z21)) | AA33: =IF(Assumptions!AA21="","",Z33*(1+Assumptions!AA21)) | AB33: =IF(Assumptions!AB21="","",AA33*(1+Assumptions!AB21))
A34: Forecast unit cost (RMB/t) | B34: =IF(B30="","",B30) | C34: =IF(C30="","",C30) | D34: =IF(D30="","",D30) | E34: =IF(E30="","",E30) | F34: =IF(F30="","",F30) | G34: =IF(G30="","",G30) | H34: =IF(H30="","",H30) | I34: =IF(I30="","",I30) | ... R34: =IF(R30="","",R30) | S34: =IF(OR($I$30="",S31="",S32="",S33=""),"",$I$30*(S31*S32+(1-S31)*S33)) | T34: =IF(OR($I$30="",T31="",T32="",T33=""),"",$I$30*(T31*T32+(1-T31)*T33)) | U34: =IF(OR($I$30="",U31="",U32="",U33=""),"",$I$30*(U31*U32+(1-U31)*U33)) | V34: =IF(OR($I$30="",V31="",V32="",V33=""),"",$I$30*(V31*V32+(1-V31)*V33)) | W34: =IF(OR($I$30="",W31="",W32="",W33=""),"",$I$30*(W31*W32+(1-W31)*W33)) | X34: =IF(OR($I$30="",X31="",X32="",X33=""),"",$I$30*(X31*X32+(1-X31)*X33)) | Y34: =IF(OR($I$30="",Y31="",Y32="",Y33=""),"",$I$30*(Y31*Y32+(1-Y31)*Y33)) | Z34: =IF(OR($I$30="",Z31="",Z32="",Z33=""),"",$I$30*(Z31*Z32+(1-Z31)*Z33)) | ... AB34: =IF(OR($I$30="",AB31="",AB32="",AB33=""),"",$I$30*(AB31*AB32+(1-AB31)*AB33))
A35: Modelled product-series cost | B35: =IF(B29="","",B29) | C35: =IF(C29="","",C29) | D35: =IF(D29="","",D29) | E35: =IF(E29="","",E29) | F35: =IF(F29="","",F29) | G35: =IF(G29="","",G29) | H35: =IF(H29="","",H29) | I35: =IF(I29="","",I29) | ... R35: =IF(R29="","",R29) | S35: =IF(OR(S28="",S34=""),"",S28*S34/100) | T35: =IF(OR(T28="",T34=""),"",T28*T34/100) | U35: =IF(OR(U28="",U34=""),"",U28*U34/100) | V35: =IF(OR(V28="",V34=""),"",V28*V34/100) | W35: =IF(OR(W28="",W34=""),"",W28*W34/100) | X35: =IF(OR(X28="",X34=""),"",X28*X34/100) | Y35: =IF(OR(Y28="",Y34=""),"",Y28*Y34/100) | Z35: =IF(OR(Z28="",Z34=""),"",Z28*Z34/100) | ... AB35: =IF(OR(AB28="",AB34=""),"",AB28*AB34/100)

Sheet Segment P&L
A1: Segment P&L
A2: Historical residuals reconcile disclosed product tables to consolidated statements; forecast residuals are formula-driven.
A4: RMB mm unless stated | B4: 2018A | C4: 2019A | D4: 2020A | E4: 2021A | F4: 2022A | G4: 2023A | H4: 2024A | I4: 2025A | J4: 2024Q1A | K4: 2024Q2A | L4: 2024Q3A | M4: 2024Q4A | N4: 2025Q1A | O4: 2025Q2A | P4: 2025Q3A | Q4: 2025Q4A | R4: 2026Q1A | S4: 2026E | T4: 2027E | U4: 2028E | V4: 2026Q2E | W4: 2026Q3E | X4: 2026Q4E | Y4: 2027Q1E | Z4: 2027Q2E | AA4: 2027Q3E | AB4: 2027Q4E
A5: 聚氨酯系列
A6: Revenue | B6: ='Volume-Price'!B12 | C6: ='Volume-Price'!C12 | D6: ='Volume-Price'!D12 | E6: ='Volume-Price'!E12 | F6: ='Volume-Price'!F12 | G6: ='Volume-Price'!G12 | H6: ='Volume-Price'!H12 | I6: ='Volume-Price'!I12 | ... AB6: ='Volume-Price'!AB12
A7: Cost | B7: ='Cost Bridge'!B13 | C7: ='Cost Bridge'!C13 | D7: ='Cost Bridge'!D13 | E7: ='Cost Bridge'!E13 | F7: ='Cost Bridge'!F13 | G7: ='Cost Bridge'!G13 | H7: ='Cost Bridge'!H13 | I7: ='Cost Bridge'!I13 | ... AB7: ='Cost Bridge'!AB13
A8: Gross profit | B8: =IF(OR(B6="",B7=""),"",B6-B7) | C8: =IF(OR(C6="",C7=""),"",C6-C7) | D8: =IF(OR(D6="",D7=""),"",D6-D7) | E8: =IF(OR(E6="",E7=""),"",E6-E7) | F8: =IF(OR(F6="",F7=""),"",F6-F7) | G8: =IF(OR(G6="",G7=""),"",G6-G7) | H8: =IF(OR(H6="",H7=""),"",H6-H7) | I8: =IF(OR(I6="",I7=""),"",I6-I7) | ... AB8: =IF(OR(AB6="",AB7=""),"",AB6-AB7)
A9: Gross margin | B9: =IFERROR(IF(OR(B6="",B6=0,B8=""),"",B8/B6),"") | C9: =IFERROR(IF(OR(C6="",C6=0,C8=""),"",C8/C6),"") | D9: =IFERROR(IF(OR(D6="",D6=0,D8=""),"",D8/D6),"") | E9: =IFERROR(IF(OR(E6="",E6=0,E8=""),"",E8/E6),"") | F9: =IFERROR(IF(OR(F6="",F6=0,F8=""),"",F8/F6),"") | G9: =IFERROR(IF(OR(G6="",G6=0,G8=""),"",G8/G6),"") | H9: =IFERROR(IF(OR(H6="",H6=0,H8=""),"",H8/H6),"") | I9: =IFERROR(IF(OR(I6="",I6=0,I8=""),"",I8/I6),"") | ... AB9: =IFERROR(IF(OR(AB6="",AB6=0,AB8=""),"",AB8/AB6),"")
A11: 石化系列
A12: Revenue | B12: ='Volume-Price'!B22 | C12: ='Volume-Price'!C22 | D12: ='Volume-Price'!D22 | E12: ='Volume-Price'!E22 | F12: ='Volume-Price'!F22 | G12: ='Volume-Price'!G22 | H12: ='Volume-Price'!H22 | I12: ='Volume-Price'!I22 | ... AB12: ='Volume-Price'!AB22
A13: Cost | B13: ='Cost Bridge'!B24 | C13: ='Cost Bridge'!C24 | D13: ='Cost Bridge'!D24 | E13: ='Cost Bridge'!E24 | F13: ='Cost Bridge'!F24 | G13: ='Cost Bridge'!G24 | H13: ='Cost Bridge'!H24 | I13: ='Cost Bridge'!I24 | ... AB13: ='Cost Bridge'!AB24
A14: Gross profit | B14: =IF(OR(B12="",B13=""),"",B12-B13) | C14: =IF(OR(C12="",C13=""),"",C12-C13) | D14: =IF(OR(D12="",D13=""),"",D12-D13) | E14: =IF(OR(E12="",E13=""),"",E12-E13) | F14: =IF(OR(F12="",F13=""),"",F12-F13) | G14: =IF(OR(G12="",G13=""),"",G12-G13) | H14: =IF(OR(H12="",H13=""),"",H12-H13) | I14: =IF(OR(I12="",I13=""),"",I12-I13) | ... AB14: =IF(OR(AB12="",AB13=""),"",AB12-AB13)
A15: Gross margin | B15: =IFERROR(IF(OR(B12="",B12=0,B14=""),"",B14/B12),"") | C15: =IFERROR(IF(OR(C12="",C12=0,C14=""),"",C14/C12),"") | D15: =IFERROR(IF(OR(D12="",D12=0,D14=""),"",D14/D12),"") | E15: =IFERROR(IF(OR(E12="",E12=0,E14=""),"",E14/E12),"") | F15: =IFERROR(IF(OR(F12="",F12=0,F14=""),"",F14/F12),"") | G15: =IFERROR(IF(OR(G12="",G12=0,G14=""),"",G14/G12),"") | H15: =IFERROR(IF(OR(H12="",H12=0,H14=""),"",H14/H12),"") | I15: =IFERROR(IF(OR(I12="",I12=0,I14=""),"",I14/I12),"") | ... AB15: =IFERROR(IF(OR(AB12="",AB12=0,AB14=""),"",AB14/AB12),"")
A17: 精细化学品及新材料系列
A18: Revenue | B18: ='Volume-Price'!B32 | C18: ='Volume-Price'!C32 | D18: ='Volume-Price'!D32 | E18: ='Volume-Price'!E32 | F18: ='Volume-Price'!F32 | G18: ='Volume-Price'!G32 | H18: ='Volume-Price'!H32 | I18: ='Volume-Price'!I32 | ... AB18: ='Volume-Price'!AB32
A19: Cost | B19: ='Cost Bridge'!B35 | C19: ='Cost Bridge'!C35 | D19: ='Cost Bridge'!D35 | E19: ='Cost Bridge'!E35 | F19: ='Cost Bridge'!F35 | G19: ='Cost Bridge'!G35 | H19: ='Cost Bridge'!H35 | I19: ='Cost Bridge'!I35 | ... AB19: ='Cost Bridge'!AB35
A20: Gross profit | B20: =IF(OR(B18="",B19=""),"",B18-B19) | C20: =IF(OR(C18="",C19=""),"",C18-C19) | D20: =IF(OR(D18="",D19=""),"",D18-D19) | E20: =IF(OR(E18="",E19=""),"",E18-E19) | F20: =IF(OR(F18="",F19=""),"",F18-F19) | G20: =IF(OR(G18="",G19=""),"",G18-G19) | H20: =IF(OR(H18="",H19=""),"",H18-H19) | I20: =IF(OR(I18="",I19=""),"",I18-I19) | ... AB20: =IF(OR(AB18="",AB19=""),"",AB18-AB19)
A21: Gross margin | B21: =IFERROR(IF(OR(B18="",B18=0,B20=""),"",B20/B18),"") | C21: =IFERROR(IF(OR(C18="",C18=0,C20=""),"",C20/C18),"") | D21: =IFERROR(IF(OR(D18="",D18=0,D20=""),"",D20/D18),"") | E21: =IFERROR(IF(OR(E18="",E18=0,E20=""),"",E20/E18),"") | F21: =IFERROR(IF(OR(F18="",F18=0,F20=""),"",F20/F18),"") | G21: =IFERROR(IF(OR(G18="",G18=0,G20=""),"",G20/G18),"") | H21: =IFERROR(IF(OR(H18="",H18=0,H20=""),"",H20/H18),"") | I21: =IFERROR(IF(OR(I18="",I18=0,I20=""),"",I20/I18),"") | ... AB21: =IFERROR(IF(OR(AB18="",AB18=0,AB20=""),"",AB20/AB18),"")
A23: Other, eliminations and reconciliation
A24: Other / residual revenue — disclosed or modelled | S24: =IF(Assumptions!S28="","",I30*(1+Assumptions!S28)) | T24: =IF(Assumptions!T28="","",S30*(1+Assumptions!T28)) | U24: =IF(Assumptions!U28="","",T30*(1+Assumptions!U28)) | V24: =IF(Assumptions!V28="","",R30*(1+Assumptions!V28)) | W24: =IF(Assumptions!W28="","",V30*(1+Assumptions!W28)) | X24: =IF(Assumptions!X28="","",W30*(1+Assumptions!X28)) | Y24: =IF(Assumptions!Y28="","",X30*(1+Assumptions!Y28)) | Z24: =IF(Assumptions!Z28="","",Y30*(1+Assumptions!Z28)) | AA24: =IF(Assumptions!AA28="","",Z30*(1+Assumptions!AA28)) | AB24: =IF(Assumptions!AB28="","",AA30*(1+Assumptions!AB28))
A25: Other / residual cost — disclosed or modelled | S25: =IF(Assumptions!S28="","",I25*(1+Assumptions!S28)) | T25: =IF(Assumptions!T28="","",S25*(1+Assumptions!T28)) | U25: =IF(Assumptions!U28="","",T25*(1+Assumptions!U28)) | V25: =IF(Assumptions!V28="","",$I$31/4*(1+Assumptions!V28)) | W25: =IF(Assumptions!W28="","",V25*(1+Assumptions!W28)) | X25: =IF(Assumptions!X28="","",W25*(1+Assumptions!X28)) | Y25: =IF(Assumptions!Y28="","",X25*(1+Assumptions!Y28)) | Z25: =IF(Assumptions!Z28="","",Y25*(1+Assumptions!Z28)) | AA25: =IF(Assumptions!AA28="","",Z25*(1+Assumptions!AA28)) | AB25: =IF(Assumptions!AB28="","",AA25*(1+Assumptions!AB28))
A26: Eliminations revenue — disclosed
A27: Eliminations cost — disclosed
A28: Product-table subtotal — revenue | B28: =IF(COUNT(B6,B12,B18)=0,"",SUM(B6,B12,B18,B24,B26)) | C28: =IF(COUNT(C6,C12,C18)=0,"",SUM(C6,C12,C18,C24,C26)) | D28: =IF(COUNT(D6,D12,D18)=0,"",SUM(D6,D12,D18,D24,D26)) | E28: =IF(COUNT(E6,E12,E18)=0,"",SUM(E6,E12,E18,E24,E26)) | F28: =IF(COUNT(F6,F12,F18)=0,"",SUM(F6,F12,F18,F24,F26)) | G28: =IF(COUNT(G6,G12,G18)=0,"",SUM(G6,G12,G18,G24,G26)) | H28: =IF(COUNT(H6,H12,H18)=0,"",SUM(H6,H12,H18,H24,H26)) | I28: =IF(COUNT(I6,I12,I18)=0,"",SUM(I6,I12,I18,I24,I26)) | ... AB28: =IF(COUNT(AB6,AB12,AB18)=0,"",SUM(AB6,AB12,AB18,AB24,AB26))
A29: Product-table subtotal — cost | B29: =IF(COUNT(B7,B13,B19)=0,"",SUM(B7,B13,B19,B25,B27)) | C29: =IF(COUNT(C7,C13,C19)=0,"",SUM(C7,C13,C19,C25,C27)) | D29: =IF(COUNT(D7,D13,D19)=0,"",SUM(D7,D13,D19,D25,D27)) | E29: =IF(COUNT(E7,E13,E19)=0,"",SUM(E7,E13,E19,E25,E27)) | F29: =IF(COUNT(F7,F13,F19)=0,"",SUM(F7,F13,F19,F25,F27)) | G29: =IF(COUNT(G7,G13,G19)=0,"",SUM(G7,G13,G19,G25,G27)) | H29: =IF(COUNT(H7,H13,H19)=0,"",SUM(H7,H13,H19,H25,H27)) | I29: =IF(COUNT(I7,I13,I19)=0,"",SUM(I7,I13,I19,I25,I27)) | ... AB29: =IF(COUNT(AB7,AB13,AB19)=0,"",SUM(AB7,AB13,AB19,AB25,AB27))
A30: Boundary residual — revenue | B30: =IF('Consol P&L'!B$6="","",'Consol P&L'!B$6-IF(B28="",0,B28)) | C30: =IF('Consol P&L'!C$6="","",'Consol P&L'!C$6-IF(C28="",0,C28)) | D30: =IF('Consol P&L'!D$6="","",'Consol P&L'!D$6-IF(D28="",0,D28)) | E30: =IF('Consol P&L'!E$6="","",'Consol P&L'!E$6-IF(E28="",0,E28)) | F30: =IF('Consol P&L'!F$6="","",'Consol P&L'!F$6-IF(F28="",0,F28)) | G30: =IF('Consol P&L'!G$6="","",'Consol P&L'!G$6-IF(G28="",0,G28)) | H30: =IF('Consol P&L'!H$6="","",'Consol P&L'!H$6-IF(H28="",0,H28)) | I30: =IF('Consol P&L'!I$6="","",'Consol P&L'!I$6-IF(I28="",0,I28)) | ... R30: =IF('Consol P&L'!R$6="","",'Consol P&L'!R$6-IF(R28="",0,R28)) | S30: ="" | T30: ="" | U30: ="" | V30: ="" | W30: ="" | X30: ="" | Y30: ="" | Z30: ="" | ... AB30: =""
A31: Boundary residual — cost | B31: =IF('Consol P&L'!B$9="","",'Consol P&L'!B$9-IF(B29="",0,B29)) | C31: =IF('Consol P&L'!C$9="","",'Consol P&L'!C$9-IF(C29="",0,C29)) | D31: =IF('Consol P&L'!D$9="","",'Consol P&L'!D$9-IF(D29="",0,D29)) | E31: =IF('Consol P&L'!E$9="","",'Consol P&L'!E$9-IF(E29="",0,E29)) | F31: =IF('Consol P&L'!F$9="","",'Consol P&L'!F$9-IF(F29="",0,F29)) | G31: =IF('Consol P&L'!G$9="","",'Consol P&L'!G$9-IF(G29="",0,G29)) | H31: =IF('Consol P&L'!H$9="","",'Consol P&L'!H$9-IF(H29="",0,H29)) | I31: =IF('Consol P&L'!I$9="","",'Consol P&L'!I$9-IF(I29="",0,I29)) | ... R31: =IF('Consol P&L'!R$9="","",'Consol P&L'!R$9-IF(R29="",0,R29)) | S31: ="" | T31: ="" | U31: ="" | V31: ="" | W31: ="" | X31: ="" | Y31: ="" | Z31: ="" | ... AB31: =""
A32: Consolidated schedule revenue | B32: =IF('Consol P&L'!B$6="","",SUM(B28,B30)) | C32: =IF('Consol P&L'!C$6="","",SUM(C28,C30)) | D32: =IF('Consol P&L'!D$6="","",SUM(D28,D30)) | E32: =IF('Consol P&L'!E$6="","",SUM(E28,E30)) | F32: =IF('Consol P&L'!F$6="","",SUM(F28,F30)) | G32: =IF('Consol P&L'!G$6="","",SUM(G28,G30)) | H32: =IF('Consol P&L'!H$6="","",SUM(H28,H30)) | I32: =IF('Consol P&L'!I$6="","",SUM(I28,I30)) | ... R32: =IF('Consol P&L'!R$6="","",SUM(R28,R30)) | S32: =IF(S28="","",S28) | T32: =IF(T28="","",T28) | U32: =IF(U28="","",U28) | V32: =IF(V28="","",V28) | W32: =IF(W28="","",W28) | X32: =IF(X28="","",X28) | Y32: =IF(Y28="","",Y28) | Z32: =IF(Z28="","",Z28) | ... AB32: =IF(AB28="","",AB28)
A33: Consolidated schedule cost | B33: =IF('Consol P&L'!B$9="","",SUM(B29,B31)) | C33: =IF('Consol P&L'!C$9="","",SUM(C29,C31)) | D33: =IF('Consol P&L'!D$9="","",SUM(D29,D31)) | E33: =IF('Consol P&L'!E$9="","",SUM(E29,E31)) | F33: =IF('Consol P&L'!F$9="","",SUM(F29,F31)) | G33: =IF('Consol P&L'!G$9="","",SUM(G29,G31)) | H33: =IF('Consol P&L'!H$9="","",SUM(H29,H31)) | I33: =IF('Consol P&L'!I$9="","",SUM(I29,I31)) | ... R33: =IF('Consol P&L'!R$9="","",SUM(R29,R31)) | S33: =IF(S29="","",S29) | T33: =IF(T29="","",T29) | U33: =IF(U29="","",U29) | V33: =IF(V29="","",V29) | W33: =IF(W29="","",W29) | X33: =IF(X29="","",X29) | Y33: =IF(Y29="","",Y29) | Z33: =IF(Z29="","",Z29) | ... AB33: =IF(AB29="","",AB29)
A34: Consolidated schedule gross profit | B34: =IF(OR(B32="",B33=""),"",B32-B33) | C34: =IF(OR(C32="",C33=""),"",C32-C33) | D34: =IF(OR(D32="",D33=""),"",D32-D33) | E34: =IF(OR(E32="",E33=""),"",E32-E33) | F34: =IF(OR(F32="",F33=""),"",F32-F33) | G34: =IF(OR(G32="",G33=""),"",G32-G33) | H34: =IF(OR(H32="",H33=""),"",H32-H33) | I34: =IF(OR(I32="",I33=""),"",I32-I33) | ... AB34: =IF(OR(AB32="",AB33=""),"",AB32-AB33)
A35: Consolidated schedule gross margin | B35: =IFERROR(IF(OR(B32="",B32=0,B34=""),"",B34/B32),"") | C35: =IFERROR(IF(OR(C32="",C32=0,C34=""),"",C34/C32),"") | D35: =IFERROR(IF(OR(D32="",D32=0,D34=""),"",D34/D32),"") | E35: =IFERROR(IF(OR(E32="",E32=0,E34=""),"",E34/E32),"") | F35: =IFERROR(IF(OR(F32="",F32=0,F34=""),"",F34/F32),"") | G35: =IFERROR(IF(OR(G32="",G32=0,G34=""),"",G34/G32),"") | H35: =IFERROR(IF(OR(H32="",H32=0,H34=""),"",H34/H32),"") | I35: =IFERROR(IF(OR(I32="",I32=0,I34=""),"",I34/I32),"") | ... AB35: =IFERROR(IF(OR(AB32="",AB32=0,AB34=""),"",AB34/AB32),"")

Sheet Consol P&L
A1: Consolidated P&L
A2: Annual filing actuals and standalone quarterly filing actuals / arithmetic differences.
A4: RMB mm unless stated | B4: 2018A | C4: 2019A | D4: 2020A | E4: 2021A | F4: 2022A | G4: 2023A | H4: 2024A | I4: 2025A | J4: 2024Q1A | K4: 2024Q2A | L4: 2024Q3A | M4: 2024Q4A | N4: 2025Q1A | O4: 2025Q2A | P4: 2025Q3A | Q4: 2025Q4A | R4: 2026Q1A | S4: 2026E | T4: 2027E | U4: 2028E | V4: 2026Q2E | W4: 2026Q3E | X4: 2026Q4E | Y4: 2027Q1E | Z4: 2027Q2E | AA4: 2027Q3E | AB4: 2027Q4E
A5: Segment schedule revenue | B5: ='Segment P&L'!B32 | C5: ='Segment P&L'!C32 | D5: ='Segment P&L'!D32 | E5: ='Segment P&L'!E32 | F5: ='Segment P&L'!F32 | G5: ='Segment P&L'!G32 | H5: ='Segment P&L'!H32 | I5: ='Segment P&L'!I32 | ... AB5: ='Segment P&L'!AB32
A6: Consolidated revenue — filing actual / forecast | S6: =IF(S5="","",S5) | T6: =IF(T5="","",T5) | U6: =IF(U5="","",U5) | V6: =IF(V5="","",V5) | W6: =IF(W5="","",W5) | X6: =IF(X5="","",X5) | Y6: =IF(Y5="","",Y5) | Z6: =IF(Z5="","",Z5) | ... AB6: =IF(AB5="","",AB5)
A7: Revenue bridge difference | B7: =IF(OR(B5="",B6=""),"",B5-B6) | C7: =IF(OR(C5="",C6=""),"",C5-C6) | D7: =IF(OR(D5="",D6=""),"",D5-D6) | E7: =IF(OR(E5="",E6=""),"",E5-E6) | F7: =IF(OR(F5="",F6=""),"",F5-F6) | G7: =IF(OR(G5="",G6=""),"",G5-G6) | H7: =IF(OR(H5="",H6=""),"",H5-H6) | I7: =IF(OR(I5="",I6=""),"",I5-I6) | ... AB7: =IF(OR(AB5="",AB6=""),"",AB5-AB6)
A8: Segment schedule cost | B8: ='Segment P&L'!B33 | C8: ='Segment P&L'!C33 | D8: ='Segment P&L'!D33 | E8: ='Segment P&L'!E33 | F8: ='Segment P&L'!F33 | G8: ='Segment P&L'!G33 | H8: ='Segment P&L'!H33 | I8: ='Segment P&L'!I33 | ... AB8: ='Segment P&L'!AB33
A9: Consolidated cost of sales — filing actual / forecast | S9: =IF(S8="","",S8) | T9: =IF(T8="","",T8) | U9: =IF(U8="","",U8) | V9: =IF(V8="","",V8) | W9: =IF(W8="","",W8) | X9: =IF(X8="","",X8) | Y9: =IF(Y8="","",Y8) | Z9: =IF(Z8="","",Z8) | ... AB9: =IF(AB8="","",AB8)
A10: Cost bridge difference | B10: =IF(OR(B8="",B9=""),"",B8-B9) | C10: =IF(OR(C8="",C9=""),"",C8-C9) | D10: =IF(OR(D8="",D9=""),"",D8-D9) | E10: =IF(OR(E8="",E9=""),"",E8-E9) | F10: =IF(OR(F8="",F9=""),"",F8-F9) | G10: =IF(OR(G8="",G9=""),"",G8-G9) | H10: =IF(OR(H8="",H9=""),"",H8-H9) | I10: =IF(OR(I8="",I9=""),"",I8-I9) | ... AB10: =IF(OR(AB8="",AB9=""),"",AB8-AB9)
A11: Gross profit | B11: =IF(OR(B6="",B9=""),"",B6-B9) | C11: =IF(OR(C6="",C9=""),"",C6-C9) | D11: =IF(OR(D6="",D9=""),"",D6-D9) | E11: =IF(OR(E6="",E9=""),"",E6-E9) | F11: =IF(OR(F6="",F9=""),"",F6-F9) | G11: =IF(OR(G6="",G9=""),"",G6-G9) | H11: =IF(OR(H6="",H9=""),"",H6-H9) | I11: =IF(OR(I6="",I9=""),"",I6-I9) | ... AB11: =IF(OR(AB6="",AB9=""),"",AB6-AB9)
A12: Gross margin | B12: =IFERROR(IF(OR(B6="",B6=0,B11=""),"",B11/B6),"") | C12: =IFERROR(IF(OR(C6="",C6=0,C11=""),"",C11/C6),"") | D12: =IFERROR(IF(OR(D6="",D6=0,D11=""),"",D11/D6),"") | E12: =IFERROR(IF(OR(E6="",E6=0,E11=""),"",E11/E6),"") | F12: =IFERROR(IF(OR(F6="",F6=0,F11=""),"",F11/F6),"") | G12: =IFERROR(IF(OR(G6="",G6=0,G11=""),"",G11/G6),"") | H12: =IFERROR(IF(OR(H6="",H6=0,H11=""),"",H11/H6),"") | I12: =IFERROR(IF(OR(I6="",I6=0,I11=""),"",I11/I6),"") | ... AB12: =IFERROR(IF(OR(AB6="",AB6=0,AB11=""),"",AB11/AB6),"")
A13: Operating profit — filing actual / forecast | S13: =IF(OR(S11="",S15=""),"",S11-S6*S15) | T13: =IF(OR(T11="",T15=""),"",T11-T6*T15) | U13: =IF(OR(U11="",U15=""),"",U11-U6*U15) | V13: =IF(OR(V11="",V15=""),"",V11-V6*V15) | W13: =IF(OR(W11="",W15=""),"",W11-W6*W15) | X13: =IF(OR(X11="",X15=""),"",X11-X6*X15) | Y13: =IF(OR(Y11="",Y15=""),"",Y11-Y6*Y15) | Z13: =IF(OR(Z11="",Z15=""),"",Z11-Z6*Z15) | ... AB13: =IF(OR(AB11="",AB15=""),"",AB11-AB6*AB15)
A14: Net operating expense / other bridge | B14: =IF(OR(B11="",B13=""),"",B11-B13) | C14: =IF(OR(C11="",C13=""),"",C11-C13) | D14: =IF(OR(D11="",D13=""),"",D11-D13) | E14: =IF(OR(E11="",E13=""),"",E11-E13) | F14: =IF(OR(F11="",F13=""),"",F11-F13) | G14: =IF(OR(G11="",G13=""),"",G11-G13) | H14: =IF(OR(H11="",H13=""),"",H11-H13) | I14: =IF(OR(I11="",I13=""),"",I11-I13) | ... R14: =IF(OR(R11="",R13=""),"",R11-R13)
A15: Net operating expense / revenue | B15: =IFERROR(IF(OR(B6="",B6=0,B14=""),"",B14/B6),"") | C15: =IFERROR(IF(OR(C6="",C6=0,C14=""),"",C14/C6),"") | D15: =IFERROR(IF(OR(D6="",D6=0,D14=""),"",D14/D6),"") | E15: =IFERROR(IF(OR(E6="",E6=0,E14=""),"",E14/E6),"") | F15: =IFERROR(IF(OR(F6="",F6=0,F14=""),"",F14/F6),"") | G15: =IFERROR(IF(OR(G6="",G6=0,G14=""),"",G14/G6),"") | H15: =IFERROR(IF(OR(H6="",H6=0,H14=""),"",H14/H6),"") | I15: =IFERROR(IF(OR(I6="",I6=0,I14=""),"",I14/I6),"") | ... R15: =IFERROR(IF(OR(R6="",R6=0,R14=""),"",R14/R6),"") | S15: =IF(Assumptions!S29="","",Assumptions!S29) | T15: =IF(Assumptions!T29="","",Assumptions!T29) | U15: =IF(Assumptions!U29="","",Assumptions!U29) | V15: =IF(Assumptions!V29="","",Assumptions!V29) | W15: =IF(Assumptions!W29="","",Assumptions!W29) | X15: =IF(Assumptions!X29="","",Assumptions!X29) | Y15: =IF(Assumptions!Y29="","",Assumptions!Y29) | Z15: =IF(Assumptions!Z29="","",Assumptions!Z29) | ... AB15: =IF(Assumptions!AB29="","",Assumptions!AB29)
A16: Attributable net income — filing actual / forecast | S16: =IF(OR(S13="",S17=""),"",S13*S17) | T16: =IF(OR(T13="",T17=""),"",T13*T17) | U16: =IF(OR(U13="",U17=""),"",U13*U17) | V16: =IF(OR(V13="",V17=""),"",V13*V17) | W16: =IF(OR(W13="",W17=""),"",W13*W17) | X16: =IF(OR(X13="",X17=""),"",X13*X17) | Y16: =IF(OR(Y13="",Y17=""),"",Y13*Y17) | Z16: =IF(OR(Z13="",Z17=""),"",Z13*Z17) | ... AB16: =IF(OR(AB13="",AB17=""),"",AB13*AB17)
A17: Operating profit to attributable NI conversion | B17: =IFERROR(IF(OR(B13="",B13=0,B16=""),"",B16/B13),"") | C17: =IFERROR(IF(OR(C13="",C13=0,C16=""),"",C16/C13),"") | D17: =IFERROR(IF(OR(D13="",D13=0,D16=""),"",D16/D13),"") | E17: =IFERROR(IF(OR(E13="",E13=0,E16=""),"",E16/E13),"") | F17: =IFERROR(IF(OR(F13="",F13=0,F16=""),"",F16/F13),"") | G17: =IFERROR(IF(OR(G13="",G13=0,G16=""),"",G16/G13),"") | H17: =IFERROR(IF(OR(H13="",H13=0,H16=""),"",H16/H13),"") | I17: =IFERROR(IF(OR(I13="",I13=0,I16=""),"",I16/I13),"") | ... R17: =IFERROR(IF(OR(R13="",R13=0,R16=""),"",R16/R13),"") | S17: =IF(Assumptions!S30="","",Assumptions!S30) | T17: =IF(Assumptions!T30="","",Assumptions!T30) | U17: =IF(Assumptions!U30="","",Assumptions!U30) | V17: =IF(Assumptions!V30="","",Assumptions!V30) | W17: =IF(Assumptions!W30="","",Assumptions!W30) | X17: =IF(Assumptions!X30="","",Assumptions!X30) | Y17: =IF(Assumptions!Y30="","",Assumptions!Y30) | Z17: =IF(Assumptions!Z30="","",Assumptions!Z30) | ... AB17: =IF(Assumptions!AB30="","",Assumptions!AB30)

Sheet Cash Flow
A1: Cash Flow
A2: Capex is cash paid to acquire/build fixed, intangible and other long-term assets.
A4: RMB mm unless stated | B4: 2018A | C4: 2019A | D4: 2020A | E4: 2021A | F4: 2022A | G4: 2023A | H4: 2024A | I4: 2025A | J4: 2024Q1A | K4: 2024Q2A | L4: 2024Q3A | M4: 2024Q4A | N4: 2025Q1A | O4: 2025Q2A | P4: 2025Q3A | Q4: 2025Q4A | R4: 2026Q1A | S4: 2026E | T4: 2027E | U4: 2028E | V4: 2026Q2E | W4: 2026Q3E | X4: 2026Q4E | Y4: 2027Q1E | Z4: 2027Q2E | AA4: 2027Q3E | AB4: 2027Q4E
A5: Operating cash flow (CFO) | S5: =IF('Consol P&L'!S16="","",'Consol P&L'!S16*IFERROR(I8,1)) | T5: =IF('Consol P&L'!T16="","",'Consol P&L'!T16*IFERROR(I8,1)) | U5: =IF('Consol P&L'!U16="","",'Consol P&L'!U16*IFERROR(I8,1)) | V5: =IF('Consol P&L'!V16="","",'Consol P&L'!V16*IFERROR(R8,1)) | W5: =IF('Consol P&L'!W16="","",'Consol P&L'!W16*IFERROR(R8,1)) | X5: =IF('Consol P&L'!X16="","",'Consol P&L'!X16*IFERROR(R8,1)) | Y5: =IF('Consol P&L'!Y16="","",'Consol P&L'!Y16*IFERROR(R8,1)) | Z5: =IF('Consol P&L'!Z16="","",'Consol P&L'!Z16*IFERROR(R8,1)) | AA5: =IF('Consol P&L'!AA16="","",'Consol P&L'!AA16*IFERROR(R8,1)) | AB5: =IF('Consol P&L'!AB16="","",'Consol P&L'!AB16*IFERROR(R8,1))
A6: Capital expenditure — cash outflow | S6: =IF(OR('Consol P&L'!S6="",Assumptions!S31=""),"",'Consol P&L'!S6*Assumptions!S31) | T6: =IF(OR('Consol P&L'!T6="",Assumptions!T31=""),"",'Consol P&L'!T6*Assumptions!T31) | U6: =IF(OR('Consol P&L'!U6="",Assumptions!U31=""),"",'Consol P&L'!U6*Assumptions!U31) | V6: =IF(OR('Consol P&L'!V6="",Assumptions!V31=""),"",'Consol P&L'!V6*Assumptions!V31) | W6: =IF(OR('Consol P&L'!W6="",Assumptions!W31=""),"",'Consol P&L'!W6*Assumptions!W31) | X6: =IF(OR('Consol P&L'!X6="",Assumptions!X31=""),"",'Consol P&L'!X6*Assumptions!X31) | Y6: =IF(OR('Consol P&L'!Y6="",Assumptions!Y31=""),"",'Consol P&L'!Y6*Assumptions!Y31) | Z6: =IF(OR('Consol P&L'!Z6="",Assumptions!Z31=""),"",'Consol P&L'!Z6*Assumptions!Z31) | ... AB6: =IF(OR('Consol P&L'!AB6="",Assumptions!AB31=""),"",'Consol P&L'!AB6*Assumptions!AB31)
A7: Simplified free cash flow | B7: =IF(OR(B5="",B6=""),"",B5-B6) | C7: =IF(OR(C5="",C6=""),"",C5-C6) | D7: =IF(OR(D5="",D6=""),"",D5-D6) | E7: =IF(OR(E5="",E6=""),"",E5-E6) | F7: =IF(OR(F5="",F6=""),"",F5-F6) | G7: =IF(OR(G5="",G6=""),"",G5-G6) | H7: =IF(OR(H5="",H6=""),"",H5-H6) | I7: =IF(OR(I5="",I6=""),"",I5-I6) | ... AB7: =IF(OR(AB5="",AB6=""),"",AB5-AB6)
A8: CFO / attributable net income | B8: =IFERROR(IF(OR(B5="",'Consol P&L'!B16="",'Consol P&L'!B16=0),"",B5/'Consol P&L'!B16),"") | C8: =IFERROR(IF(OR(C5="",'Consol P&L'!C16="",'Consol P&L'!C16=0),"",C5/'Consol P&L'!C16),"") | D8: =IFERROR(IF(OR(D5="",'Consol P&L'!D16="",'Consol P&L'!D16=0),"",D5/'Consol P&L'!D16),"") | E8: =IFERROR(IF(OR(E5="",'Consol P&L'!E16="",'Consol P&L'!E16=0),"",E5/'Consol P&L'!E16),"") | F8: =IFERROR(IF(OR(F5="",'Consol P&L'!F16="",'Consol P&L'!F16=0),"",F5/'Consol P&L'!F16),"") | G8: =IFERROR(IF(OR(G5="",'Consol P&L'!G16="",'Consol P&L'!G16=0),"",G5/'Consol P&L'!G16),"") | H8: =IFERROR(IF(OR(H5="",'Consol P&L'!H16="",'Consol P&L'!H16=0),"",H5/'Consol P&L'!H16),"") | I8: =IFERROR(IF(OR(I5="",'Consol P&L'!I16="",'Consol P&L'!I16=0),"",I5/'Consol P&L'!I16),"") | ... AB8: =IFERROR(IF(OR(AB5="",'Consol P&L'!AB16="",'Consol P&L'!AB16=0),"",AB5/'Consol P&L'!AB16),"")
A9: Capex / consolidated revenue | B9: =IFERROR(IF(OR(B6="",'Consol P&L'!B6="",'Consol P&L'!B6=0),"",B6/'Consol P&L'!B6),"") | C9: =IFERROR(IF(OR(C6="",'Consol P&L'!C6="",'Consol P&L'!C6=0),"",C6/'Consol P&L'!C6),"") | D9: =IFERROR(IF(OR(D6="",'Consol P&L'!D6="",'Consol P&L'!D6=0),"",D6/'Consol P&L'!D6),"") | E9: =IFERROR(IF(OR(E6="",'Consol P&L'!E6="",'Consol P&L'!E6=0),"",E6/'Consol P&L'!E6),"") | F9: =IFERROR(IF(OR(F6="",'Consol P&L'!F6="",'Consol P&L'!F6=0),"",F6/'Consol P&L'!F6),"") | G9: =IFERROR(IF(OR(G6="",'Consol P&L'!G6="",'Consol P&L'!G6=0),"",G6/'Consol P&L'!G6),"") | H9: =IFERROR(IF(OR(H6="",'Consol P&L'!H6="",'Consol P&L'!H6=0),"",H6/'Consol P&L'!H6),"") | I9: =IFERROR(IF(OR(I6="",'Consol P&L'!I6="",'Consol P&L'!I6=0),"",I6/'Consol P&L'!I6),"") | ... AB9: =IFERROR(IF(OR(AB6="",'Consol P&L'!AB6="",'Consol P&L'!AB6=0),"",AB6/'Consol P&L'!AB6),"")

Sheet Spread Beta
A1: Spread Beta
A2: N<8 comparable quarterly observations: proportional sensitivity only; no regression beta.
A4: Field | B4: Value | C4: Unit / interpretation | D4: Low | E4: Base | F4: High | G4: Source / note | H4: Status
A5: Selected method | B5: Pending company data | C5: text | G5: N<8 quarterly observations; no regression. | H5: OK
A6: Comparable quarterly sample N | B6: 0 | C6: quarters | G6: 2024Q1/Q3, 2025Q1/Q3, 2026Q1 only. | H6: OK
A7: Regression eligibility | B7: No | C7: requires >=8 quarters | G7: Gate enforced. | H7: OK
A8: Sensitivity factor | C8: benzene factor | G8: Model methodology assumption; not a filing fact. | H8: OK
A9: Historical data status | B9: Template | C9: period coverage | G9: Quarterly segment costs intentionally blank. | H9: OK

Sheet Sources
A1: Sources
A2: One row per hardcoded model cell; disclosure gaps are explicit and use Cell="-".
A4: Sheet | B4: Cell | C4: Field | D4: Status type | E4: Period | F4: Source / document | G4: Document date | H4: Page / reference | I4: URL | J4: Unit | K4: Boundary / methodology note | L4: Verified?
A5: All period sheets | B5: - | C5: Period layout standard | D5: Template standard | E5: 2018A–2028E / 2024Q1A–2027Q4E | F5: references/templates/chem-model-template.md | G5: 2026-07-27 | H5: New period standard | I5: /Users/everflow/.openclaw/workspace-chem/references/templates/chem-model-template.md | J5: N/A | K5: Annual history 2018A–2025A; quarterly history 2024Q1A–2026Q1A; annual forecast 2026E–2028E; quarterly forecast 2026Q2E–2027Q4E. | L5: Yes

Sheet Checks
A1: Checks
A2: All checks must be OK after LibreOffice recalculation.
A4: Check | B4: Value / difference | C4: Tolerance | D4: Status | E4: Notes | F4: Last run
